Workbook
Name ClientCodeList: OFFSET(HOLIDAYS!$H$12,0,0,COUNTA(HOLIDAYS!$H$12:$H$500),1)
Name ClientNameList: OFFSET(HOLIDAYS!$H$3,0,0,COUNTA(HOLIDAYS!$H$3:$H$200),1)
Name COM: '[1]TIME SHEET 2.67'!$AY$8:$AY$58
Name COM: '[1]TIME SHEET 2.67'!$AY$8:$AY$58
Name COM: 'TIME SHEET'!$AY$8:$AY$60
Name list: '[1]TIME SHEET 2.67'!$AS$8:$AS$19
Name list: '[1]TIME SHEET 2.67'!$AS$8:$AS$19
Name list: 'TIME SHEET'!$AS$8:$AS$19
Name list: '[1]TIME SHEET 1.67'!$AS$8:$AS$19
Name PER: '[1]TIME SHEET 2.67'!$BA$8:$BA$12
Name PER: '[1]TIME SHEET 2.67'!$BA$8:$BA$12
Name PER: 'TIME SHEET'!$BA$8:$BA$10
Name PER: '[1]TIME SHEET 1.67'!$BA$8:$BA$12
Name PeriodList: OFFSET(HOLIDAYS!$I$3,0,0,COUNTA(HOLIDAYS!$I$3:$I$200),1)
Name YEAR: '[1]TIME SHEET 2.67'!$AU$8:$AU$12
Name YEAR: '[1]TIME SHEET 2.67'!$AU$8:$AU$12
Name YEAR: 'TIME SHEET'!$AU$8:$AU$13
Name YEAR: '[1]TIME SHEET 1.67'!$AU$8:$AU$12

Sheet TIME SHEET
A1: MONTHLY TIME SHEET | AN1: ชั่วโมงมาตรฐาน/วัน (ชม.) | AO1: 8
A2: Dr.Virach & Associates
A3: Month | C3: ธันวาคม | E3: Year | F3: 2569 | Y3: NAME | AF3: DIVISION
A4: DAY | G4: 1 | H4: 2 | I4: 3 | J4: 4 | K4: 5 | L4: 6 | M4: 7 | N4: 8 | O4: 9 | P4: 10 | Q4: 11 | R4: 12 | S4: 13 | T4: 14 | U4: 15 | V4: 16 | W4: 17 | X4: 18 | Y4: 19 | Z4: 20 | AA4: 21 | AB4: 22 | AC4: 23 | AD4: 24 | AE4: 25 | AF4: 26 | AG4: 27 | AH4: 28 | AI4: 29 | AJ4: 30 | AK4: 31 | AL4: TOTAL
A5: CLIENT NAME
A6: 1 | B6: {=IFERROR(INDEX(_xlfn._xlws.FILTER(ClientCodeList,COUNTIF('TIME REPORT'!$E$6:$E$37,ClientCodeList)>0),ROWS($B$6:B6)),"")} | D6: {=IF($B6="","",IFERROR(INDEX('TIME REPORT'!$H$6:$H$37,MATCH(1,('TIME REPORT'!$E$6:$E$37=$B6)*('TIME REPORT'!$H$6:$H$37<>""),0)),""))} | G6: =IF($B6="","",SUMIFS('TIME REPORT'!$N$6:$N$37,'TIME REPORT'!$A$6:$A$37,G$4,'TIME REPORT'!$E$6:$E$37,$B6)+SUMIFS('TIME REPORT'!$P$6:$P$37,'TIME REPORT'!$A$6:$A$37,G$4,'TIME REPORT'!$E$6:$E$37,$B6)/60) | H6: =IF($B6="","",SUMIFS('TIME REPORT'!$N$6:$N$37,'TIME REPORT'!$A$6:$A$37,H$4,'TIME REPORT'!$E$6:$E$37,$B6)+SUMIFS('TIME REPORT'!$P$6:$P$37,'TIME REPORT'!$A$6:$A$37,H$4,'TIME REPORT'!$E$6:$E$37,$B6)/60) | I6: =IF($B6="","",SUMIFS('TIME REPORT'!$N$6:$N$37,'TIME REPORT'!$A$6:$A$37,I$4,'TIME REPORT'!$E$6:$E$37,$B6)+SUMIFS('TIME REPORT'!$P$6:$P$37,'TIME REPORT'!$A$6:$A$37,I$4,'TIME REPORT'!$E$6:$E$37,$B6)/60) | J6: =IF($B6="","",SUMIFS('TIME REPORT'!$N$6:$N$37,'TIME REPORT'!$A$6:$A$37,J$4,'TIME REPORT'!$E$6:$E$37,$B6)+SUMIFS('TIME REPORT'!$P$6:$P$37,'TIME REPORT'!$A$6:$A$37,J$4,'TIME REPORT'!$E$6:$E$37,$B6)/60) | K6: =IF($B6="","",SUMIFS('TIME REPORT'!$N$6:$N$37,'TIME REPORT'!$A$6:$A$37,K$4,'TIME REPORT'!$E$6:$E$37,$B6)+SUMIFS('TIME REPORT'!$P$6:$P$37,'TIME REPORT'!$A$6:$A$37,K$4,'TIME REPORT'!$E$6:$E$37,$B6)/60) | L6: =IF($B6="","",SUMIFS('TIME REPORT'!$N$6:$N$37,'TIME REPORT'!$A$6:$A$37,L$4,'TIME REPORT'!$E$6:$E$37,$B6)+SUMIFS('TIME REPORT'!$P$6:$P$37,'TIME REPORT'!$A$6:$A$37,L$4,'TIME REPORT'!$E$6:$E$37,$B6)/60) | M6: =IF($B6="","",SUMIFS('TIME REPORT'!$N$6:$N$37,'TIME REPORT'!$A$6:$A$37,M$4,'TIME REPORT'!$E$6:$E$37,$B6)+SUMIFS('TIME REPORT'!$P$6:$P$37,'TIME REPORT'!$A$6:$A$37,M$4,'TIME REPORT'!$E$6:$E$37,$B6)/60) | N6: =IF($B6="","",SUMIFS('TIME REPORT'!$N$6:$N$37,'TIME REPORT'!$A$6:$A$37,N$4,'TIME REPORT'!$E$6:$E$37,$B6)+SUMIFS('TIME REPORT'!$P$6:$P$37,'TIME REPORT'!$A$6:$A$37,N$4,'TIME REPORT'!$E$6:$E$37,$B6)/60) | ... AK6: =IF($B6="","",SUMIFS('TIME REPORT'!$N$6:$N$37,'TIME REPORT'!$A$6:$A$37,AK$4,'TIME REPORT'!$E$6:$E$37,$B6)+SUMIFS('TIME REPORT'!$P$6:$P$37,'TIME REPORT'!$A$6:$A$37,AK$4,'TIME REPORT'!$E$6:$E$37,$B6)/60) | AL6: =SUM(G6:AK6) -> 0
A7: 2 | B7: {=IFERROR(INDEX(_xlfn._xlws.FILTER(ClientCodeList,COUNTIF('TIME REPORT'!$E$6:$E$37,ClientCodeList)>0),ROWS($B$6:B7)),"")} | D7: {=IF($B7="","",IFERROR(INDEX('TIME REPORT'!$H$6:$H$37,MATCH(1,('TIME REPORT'!$E$6:$E$37=$B7)*('TIME REPORT'!$H$6:$H$37<>""),0)),""))} | G7: =IF($B7="","",SUMIFS('TIME REPORT'!$N$6:$N$37,'TIME REPORT'!$A$6:$A$37,G$4,'TIME REPORT'!$E$6:$E$37,$B7)+SUMIFS('TIME REPORT'!$P$6:$P$37,'TIME REPORT'!$A$6:$A$37,G$4,'TIME REPORT'!$E$6:$E$37,$B7)/60) | H7: =IF($B7="","",SUMIFS('TIME REPORT'!$N$6:$N$37,'TIME REPORT'!$A$6:$A$37,H$4,'TIME REPORT'!$E$6:$E$37,$B7)+SUMIFS('TIME REPORT'!$P$6:$P$37,'TIME REPORT'!$A$6:$A$37,H$4,'TIME REPORT'!$E$6:$E$37,$B7)/60) | I7: =IF($B7="","",SUMIFS('TIME REPORT'!$N$6:$N$37,'TIME REPORT'!$A$6:$A$37,I$4,'TIME REPORT'!$E$6:$E$37,$B7)+SUMIFS('TIME REPORT'!$P$6:$P$37,'TIME REPORT'!$A$6:$A$37,I$4,'TIME REPORT'!$E$6:$E$37,$B7)/60) | J7: =IF($B7="","",SUMIFS('TIME REPORT'!$N$6:$N$37,'TIME REPORT'!$A$6:$A$37,J$4,'TIME REPORT'!$E$6:$E$37,$B7)+SUMIFS('TIME REPORT'!$P$6:$P$37,'TIME REPORT'!$A$6:$A$37,J$4,'TIME REPORT'!$E$6:$E$37,$B7)/60) | K7: =IF($B7="","",SUMIFS('TIME REPORT'!$N$6:$N$37,'TIME REPORT'!$A$6:$A$37,K$4,'TIME REPORT'!$E$6:$E$37,$B7)+SUMIFS('TIME REPORT'!$P$6:$P$37,'TIME REPORT'!$A$6:$A$37,K$4,'TIME REPORT'!$E$6:$E$37,$B7)/60) | L7: =IF($B7="","",SUMIFS('TIME REPORT'!$N$6:$N$37,'TIME REPORT'!$A$6:$A$37,L$4,'TIME REPORT'!$E$6:$E$37,$B7)+SUMIFS('TIME REPORT'!$P$6:$P$37,'TIME REPORT'!$A$6:$A$37,L$4,'TIME REPORT'!$E$6:$E$37,$B7)/60) | M7: =IF($B7="","",SUMIFS('TIME REPORT'!$N$6:$N$37,'TIME REPORT'!$A$6:$A$37,M$4,'TIME REPORT'!$E$6:$E$37,$B7)+SUMIFS('TIME REPORT'!$P$6:$P$37,'TIME REPORT'!$A$6:$A$37,M$4,'TIME REPORT'!$E$6:$E$37,$B7)/60) | N7: =IF($B7="","",SUMIFS('TIME REPORT'!$N$6:$N$37,'TIME REPORT'!$A$6:$A$37,N$4,'TIME REPORT'!$E$6:$E$37,$B7)+SUMIFS('TIME REPORT'!$P$6:$P$37,'TIME REPORT'!$A$6:$A$37,N$4,'TIME REPORT'!$E$6:$E$37,$B7)/60) | ... AK7: =IF($B7="","",SUMIFS('TIME REPORT'!$N$6:$N$37,'TIME REPORT'!$A$6:$A$37,AK$4,'TIME REPORT'!$E$6:$E$37,$B7)+SUMIFS('TIME REPORT'!$P$6:$P$37,'TIME REPORT'!$A$6:$A$37,AK$4,'TIME REPORT'!$E$6:$E$37,$B7)/60) | AL7: =SUM(G7:AK7) -> 0
A8: 3 | B8: {=IFERROR(INDEX(_xlfn._xlws.FILTER(ClientCodeList,COUNTIF('TIME REPORT'!$E$6:$E$37,ClientCodeList)>0),ROWS($B$6:B8)),"")} | D8: {=IF($B8="","",IFERROR(INDEX('TIME REPORT'!$H$6:$H$37,MATCH(1,('TIME REPORT'!$E$6:$E$37=$B8)*('TIME REPORT'!$H$6:$H$37<>""),0)),""))} | G8: =IF($B8="","",SUMIFS('TIME REPORT'!$N$6:$N$37,'TIME REPORT'!$A$6:$A$37,G$4,'TIME REPORT'!$E$6:$E$37,$B8)+SUMIFS('TIME REPORT'!$P$6:$P$37,'TIME REPORT'!$A$6:$A$37,G$4,'TIME REPORT'!$E$6:$E$37,$B8)/60) | H8: =IF($B8="","",SUMIFS('TIME REPORT'!$N$6:$N$37,'TIME REPORT'!$A$6:$A$37,H$4,'TIME REPORT'!$E$6:$E$37,$B8)+SUMIFS('TIME REPORT'!$P$6:$P$37,'TIME REPORT'!$A$6:$A$37,H$4,'TIME REPORT'!$E$6:$E$37,$B8)/60) | I8: =IF($B8="","",SUMIFS('TIME REPORT'!$N$6:$N$37,'TIME REPORT'!$A$6:$A$37,I$4,'TIME REPORT'!$E$6:$E$37,$B8)+SUMIFS('TIME REPORT'!$P$6:$P$37,'TIME REPORT'!$A$6:$A$37,I$4,'TIME REPORT'!$E$6:$E$37,$B8)/60) | J8: =IF($B8="","",SUMIFS('TIME REPORT'!$N$6:$N$37,'TIME REPORT'!$A$6:$A$37,J$4,'TIME REPORT'!$E$6:$E$37,$B8)+SUMIFS('TIME REPORT'!$P$6:$P$37,'TIME REPORT'!$A$6:$A$37,J$4,'TIME REPORT'!$E$6:$E$37,$B8)/60) | K8: =IF($B8="","",SUMIFS('TIME REPORT'!$N$6:$N$37,'TIME REPORT'!$A$6:$A$37,K$4,'TIME REPORT'!$E$6:$E$37,$B8)+SUMIFS('TIME REPORT'!$P$6:$P$37,'TIME REPORT'!$A$6:$A$37,K$4,'TIME REPORT'!$E$6:$E$37,$B8)/60) | L8: =IF($B8="","",SUMIFS('TIME REPORT'!$N$6:$N$37,'TIME REPORT'!$A$6:$A$37,L$4,'TIME REPORT'!$E$6:$E$37,$B8)+SUMIFS('TIME REPORT'!$P$6:$P$37,'TIME REPORT'!$A$6:$A$37,L$4,'TIME REPORT'!$E$6:$E$37,$B8)/60) | M8: =IF($B8="","",SUMIFS('TIME REPORT'!$N$6:$N$37,'TIME REPORT'!$A$6:$A$37,M$4,'TIME REPORT'!$E$6:$E$37,$B8)+SUMIFS('TIME REPORT'!$P$6:$P$37,'TIME REPORT'!$A$6:$A$37,M$4,'TIME REPORT'!$E$6:$E$37,$B8)/60) | N8: =IF($B8="","",SUMIFS('TIME REPORT'!$N$6:$N$37,'TIME REPORT'!$A$6:$A$37,N$4,'TIME REPORT'!$E$6:$E$37,$B8)+SUMIFS('TIME REPORT'!$P$6:$P$37,'TIME REPORT'!$A$6:$A$37,N$4,'TIME REPORT'!$E$6:$E$37,$B8)/60) | ... AK8: =IF($B8="","",SUMIFS('TIME REPORT'!$N$6:$N$37,'TIME REPORT'!$A$6:$A$37,AK$4,'TIME REPORT'!$E$6:$E$37,$B8)+SUMIFS('TIME REPORT'!$P$6:$P$37,'TIME REPORT'!$A$6:$A$37,AK$4,'TIME REPORT'!$E$6:$E$37,$B8)/60) | AL8: =SUM(G8:AK8) -> 0
A9: 4 | B9: {=IFERROR(INDEX(_xlfn._xlws.FILTER(ClientCodeList,COUNTIF('TIME REPORT'!$E$6:$E$37,ClientCodeList)>0),ROWS($B$6:B9)),"")} | D9: {=IF($B9="","",IFERROR(INDEX('TIME REPORT'!$H$6:$H$37,MATCH(1,('TIME REPORT'!$E$6:$E$37=$B9)*('TIME REPORT'!$H$6:$H$37<>""),0)),""))} | G9: =IF($B9="","",SUMIFS('TIME REPORT'!$N$6:$N$37,'TIME REPORT'!$A$6:$A$37,G$4,'TIME REPORT'!$E$6:$E$37,$B9)+SUMIFS('TIME REPORT'!$P$6:$P$37,'TIME REPORT'!$A$6:$A$37,G$4,'TIME REPORT'!$E$6:$E$37,$B9)/60) | H9: =IF($B9="","",SUMIFS('TIME REPORT'!$N$6:$N$37,'TIME REPORT'!$A$6:$A$37,H$4,'TIME REPORT'!$E$6:$E$37,$B9)+SUMIFS('TIME REPORT'!$P$6:$P$37,'TIME REPORT'!$A$6:$A$37,H$4,'TIME REPORT'!$E$6:$E$37,$B9)/60) | I9: =IF($B9="","",SUMIFS('TIME REPORT'!$N$6:$N$37,'TIME REPORT'!$A$6:$A$37,I$4,'TIME REPORT'!$E$6:$E$37,$B9)+SUMIFS('TIME REPORT'!$P$6:$P$37,'TIME REPORT'!$A$6:$A$37,I$4,'TIME REPORT'!$E$6:$E$37,$B9)/60) | J9: =IF($B9="","",SUMIFS('TIME REPORT'!$N$6:$N$37,'TIME REPORT'!$A$6:$A$37,J$4,'TIME REPORT'!$E$6:$E$37,$B9)+SUMIFS('TIME REPORT'!$P$6:$P$37,'TIME REPORT'!$A$6:$A$37,J$4,'TIME REPORT'!$E$6:$E$37,$B9)/60) | K9: =IF($B9="","",SUMIFS('TIME REPORT'!$N$6:$N$37,'TIME REPORT'!$A$6:$A$37,K$4,'TIME REPORT'!$E$6:$E$37,$B9)+SUMIFS('TIME REPORT'!$P$6:$P$37,'TIME REPORT'!$A$6:$A$37,K$4,'TIME REPORT'!$E$6:$E$37,$B9)/60) | L9: =IF($B9="","",SUMIFS('TIME REPORT'!$N$6:$N$37,'TIME REPORT'!$A$6:$A$37,L$4,'TIME REPORT'!$E$6:$E$37,$B9)+SUMIFS('TIME REPORT'!$P$6:$P$37,'TIME REPORT'!$A$6:$A$37,L$4,'TIME REPORT'!$E$6:$E$37,$B9)/60) | M9: =IF($B9="","",SUMIFS('TIME REPORT'!$N$6:$N$37,'TIME REPORT'!$A$6:$A$37,M$4,'TIME REPORT'!$E$6:$E$37,$B9)+SUMIFS('TIME REPORT'!$P$6:$P$37,'TIME REPORT'!$A$6:$A$37,M$4,'TIME REPORT'!$E$6:$E$37,$B9)/60) | N9: =IF($B9="","",SUMIFS('TIME REPORT'!$N$6:$N$37,'TIME REPORT'!$A$6:$A$37,N$4,'TIME REPORT'!$E$6:$E$37,$B9)+SUMIFS('TIME REPORT'!$P$6:$P$37,'TIME REPORT'!$A$6:$A$37,N$4,'TIME REPORT'!$E$6:$E$37,$B9)/60) | ... AK9: =IF($B9="","",SUMIFS('TIME REPORT'!$N$6:$N$37,'TIME REPORT'!$A$6:$A$37,AK$4,'TIME REPORT'!$E$6:$E$37,$B9)+SUMIFS('TIME REPORT'!$P$6:$P$37,'TIME REPORT'!$A$6:$A$37,AK$4,'TIME REPORT'!$E$6:$E$37,$B9)/60) | AL9: =SUM(G9:AK9) -> 0
A10: 5 | B10: {=IFERROR(INDEX(_xlfn._xlws.FILTER(ClientCodeList,COUNTIF('TIME REPORT'!$E$6:$E$37,ClientCodeList)>0),ROWS($B$6:B10)),"")} | D10: {=IF($B10="","",IFERROR(INDEX('TIME REPORT'!$H$6:$H$37,MATCH(1,('TIME REPORT'!$E$6:$E$37=$B10)*('TIME REPORT'!$H$6:$H$37<>""),0)),""))} | G10: =IF($B10="","",SUMIFS('TIME REPORT'!$N$6:$N$37,'TIME REPORT'!$A$6:$A$37,G$4,'TIME REPORT'!$E$6:$E$37,$B10)+SUMIFS('TIME REPORT'!$P$6:$P$37,'TIME REPORT'!$A$6:$A$37,G$4,'TIME REPORT'!$E$6:$E$37,$B10)/60) | H10: =IF($B10="","",SUMIFS('TIME REPORT'!$N$6:$N$37,'TIME REPORT'!$A$6:$A$37,H$4,'TIME REPORT'!$E$6:$E$37,$B10)+SUMIFS('TIME REPORT'!$P$6:$P$37,'TIME REPORT'!$A$6:$A$37,H$4,'TIME REPORT'!$E$6:$E$37,$B10)/60) | I10: =IF($B10="","",SUMIFS('TIME REPORT'!$N$6:$N$37,'TIME REPORT'!$A$6:$A$37,I$4,'TIME REPORT'!$E$6:$E$37,$B10)+SUMIFS('TIME REPORT'!$P$6:$P$37,'TIME REPORT'!$A$6:$A$37,I$4,'TIME REPORT'!$E$6:$E$37,$B10)/60) | J10: =IF($B10="","",SUMIFS('TIME REPORT'!$N$6:$N$37,'TIME REPORT'!$A$6:$A$37,J$4,'TIME REPORT'!$E$6:$E$37,$B10)+SUMIFS('TIME REPORT'!$P$6:$P$37,'TIME REPORT'!$A$6:$A$37,J$4,'TIME REPORT'!$E$6:$E$37,$B10)/60) | K10: =IF($B10="","",SUMIFS('TIME REPORT'!$N$6:$N$37,'TIME REPORT'!$A$6:$A$37,K$4,'TIME REPORT'!$E$6:$E$37,$B10)+SUMIFS('TIME REPORT'!$P$6:$P$37,'TIME REPORT'!$A$6:$A$37,K$4,'TIME REPORT'!$E$6:$E$37,$B10)/60) | L10: =IF($B10="","",SUMIFS('TIME REPORT'!$N$6:$N$37,'TIME REPORT'!$A$6:$A$37,L$4,'TIME REPORT'!$E$6:$E$37,$B10)+SUMIFS('TIME REPORT'!$P$6:$P$37,'TIME REPORT'!$A$6:$A$37,L$4,'TIME REPORT'!$E$6:$E$37,$B10)/60) | M10: =IF($B10="","",SUMIFS('TIME REPORT'!$N$6:$N$37,'TIME REPORT'!$A$6:$A$37,M$4,'TIME REPORT'!$E$6:$E$37,$B10)+SUMIFS('TIME REPORT'!$P$6:$P$37,'TIME REPORT'!$A$6:$A$37,M$4,'TIME REPORT'!$E$6:$E$37,$B10)/60) | N10: =IF($B10="","",SUMIFS('TIME REPORT'!$N$6:$N$37,'TIME REPORT'!$A$6:$A$37,N$4,'TIME REPORT'!$E$6:$E$37,$B10)+SUMIFS('TIME REPORT'!$P$6:$P$37,'TIME REPORT'!$A$6:$A$37,N$4,'TIME REPORT'!$E$6:$E$37,$B10)/60) | ... AK10: =IF($B10="","",SUMIFS('TIME REPORT'!$N$6:$N$37,'TIME REPORT'!$A$6:$A$37,AK$4,'TIME REPORT'!$E$6:$E$37,$B10)+SUMIFS('TIME REPORT'!$P$6:$P$37,'TIME REPORT'!$A$6:$A$37,AK$4,'TIME REPORT'!$E$6:$E$37,$B10)/60) | AL10: =SUM(G10:AK10) -> 0
A11: 6 | B11: {=IFERROR(INDEX(_xlfn._xlws.FILTER(ClientCodeList,COUNTIF('TIME REPORT'!$E$6:$E$37,ClientCodeList)>0),ROWS($B$6:B11)),"")} | D11: {=IF($B11="","",IFERROR(INDEX('TIME REPORT'!$H$6:$H$37,MATCH(1,('TIME REPORT'!$E$6:$E$37=$B11)*('TIME REPORT'!$H$6:$H$37<>""),0)),""))} | G11: =IF($B11="","",SUMIFS('TIME REPORT'!$N$6:$N$37,'TIME REPORT'!$A$6:$A$37,G$4,'TIME REPORT'!$E$6:$E$37,$B11)+SUMIFS('TIME REPORT'!$P$6:$P$37,'TIME REPORT'!$A$6:$A$37,G$4,'TIME REPORT'!$E$6:$E$37,$B11)/60) | H11: =IF($B11="","",SUMIFS('TIME REPORT'!$N$6:$N$37,'TIME REPORT'!$A$6:$A$37,H$4,'TIME REPORT'!$E$6:$E$37,$B11)+SUMIFS('TIME REPORT'!$P$6:$P$37,'TIME REPORT'!$A$6:$A$37,H$4,'TIME REPORT'!$E$6:$E$37,$B11)/60) | I11: =IF($B11="","",SUMIFS('TIME REPORT'!$N$6:$N$37,'TIME REPORT'!$A$6:$A$37,I$4,'TIME REPORT'!$E$6:$E$37,$B11)+SUMIFS('TIME REPORT'!$P$6:$P$37,'TIME REPORT'!$A$6:$A$37,I$4,'TIME REPORT'!$E$6:$E$37,$B11)/60) | J11: =IF($B11="","",SUMIFS('TIME REPORT'!$N$6:$N$37,'TIME REPORT'!$A$6:$A$37,J$4,'TIME REPORT'!$E$6:$E$37,$B11)+SUMIFS('TIME REPORT'!$P$6:$P$37,'TIME REPORT'!$A$6:$A$37,J$4,'TIME REPORT'!$E$6:$E$37,$B11)/60) | K11: =IF($B11="","",SUMIFS('TIME REPORT'!$N$6:$N$37,'TIME REPORT'!$A$6:$A$37,K$4,'TIME REPORT'!$E$6:$E$37,$B11)+SUMIFS('TIME REPORT'!$P$6:$P$37,'TIME REPORT'!$A$6:$A$37,K$4,'TIME REPORT'!$E$6:$E$37,$B11)/60) | L11: =IF($B11="","",SUMIFS('TIME REPORT'!$N$6:$N$37,'TIME REPORT'!$A$6:$A$37,L$4,'TIME REPORT'!$E$6:$E$37,$B11)+SUMIFS('TIME REPORT'!$P$6:$P$37,'TIME REPORT'!$A$6:$A$37,L$4,'TIME REPORT'!$E$6:$E$37,$B11)/60) | M11: =IF($B11="","",SUMIFS('TIME REPORT'!$N$6:$N$37,'TIME REPORT'!$A$6:$A$37,M$4,'TIME REPORT'!$E$6:$E$37,$B11)+SUMIFS('TIME REPORT'!$P$6:$P$37,'TIME REPORT'!$A$6:$A$37,M$4,'TIME REPORT'!$E$6:$E$37,$B11)/60) | N11: =IF($B11="","",SUMIFS('TIME REPORT'!$N$6:$N$37,'TIME REPORT'!$A$6:$A$37,N$4,'TIME REPORT'!$E$6:$E$37,$B11)+SUMIFS('TIME REPORT'!$P$6:$P$37,'TIME REPORT'!$A$6:$A$37,N$4,'TIME REPORT'!$E$6:$E$37,$B11)/60) | ... AK11: =IF($B11="","",SUMIFS('TIME REPORT'!$N$6:$N$37,'TIME REPORT'!$A$6:$A$37,AK$4,'TIME REPORT'!$E$6:$E$37,$B11)+SUMIFS('TIME REPORT'!$P$6:$P$37,'TIME REPORT'!$A$6:$A$37,AK$4,'TIME REPORT'!$E$6:$E$37,$B11)/60) | AL11: =SUM(G11:AK11) -> 0
A12: 7 | B12: {=IFERROR(INDEX(_xlfn._xlws.FILTER(ClientCodeList,COUNTIF('TIME REPORT'!$E$6:$E$37,ClientCodeList)>0),ROWS($B$6:B12)),"")} | D12: {=IF($B12="","",IFERROR(INDEX('TIME REPORT'!$H$6:$H$37,MATCH(1,('TIME REPORT'!$E$6:$E$37=$B12)*('TIME REPORT'!$H$6:$H$37<>""),0)),""))} | G12: =IF($B12="","",SUMIFS('TIME REPORT'!$N$6:$N$37,'TIME REPORT'!$A$6:$A$37,G$4,'TIME REPORT'!$E$6:$E$37,$B12)+SUMIFS('TIME REPORT'!$P$6:$P$37,'TIME REPORT'!$A$6:$A$37,G$4,'TIME REPORT'!$E$6:$E$37,$B12)/60) | H12: =IF($B12="","",SUMIFS('TIME REPORT'!$N$6:$N$37,'TIME REPORT'!$A$6:$A$37,H$4,'TIME REPORT'!$E$6:$E$37,$B12)+SUMIFS('TIME REPORT'!$P$6:$P$37,'TIME REPORT'!$A$6:$A$37,H$4,'TIME REPORT'!$E$6:$E$37,$B12)/60) | I12: =IF($B12="","",SUMIFS('TIME REPORT'!$N$6:$N$37,'TIME REPORT'!$A$6:$A$37,I$4,'TIME REPORT'!$E$6:$E$37,$B12)+SUMIFS('TIME REPORT'!$P$6:$P$37,'TIME REPORT'!$A$6:$A$37,I$4,'TIME REPORT'!$E$6:$E$37,$B12)/60) | J12: =IF($B12="","",SUMIFS('TIME REPORT'!$N$6:$N$37,'TIME REPORT'!$A$6:$A$37,J$4,'TIME REPORT'!$E$6:$E$37,$B12)+SUMIFS('TIME REPORT'!$P$6:$P$37,'TIME REPORT'!$A$6:$A$37,J$4,'TIME REPORT'!$E$6:$E$37,$B12)/60) | K12: =IF($B12="","",SUMIFS('TIME REPORT'!$N$6:$N$37,'TIME REPORT'!$A$6:$A$37,K$4,'TIME REPORT'!$E$6:$E$37,$B12)+SUMIFS('TIME REPORT'!$P$6:$P$37,'TIME REPORT'!$A$6:$A$37,K$4,'TIME REPORT'!$E$6:$E$37,$B12)/60) | L12: =IF($B12="","",SUMIFS('TIME REPORT'!$N$6:$N$37,'TIME REPORT'!$A$6:$A$37,L$4,'TIME REPORT'!$E$6:$E$37,$B12)+SUMIFS('TIME REPORT'!$P$6:$P$37,'TIME REPORT'!$A$6:$A$37,L$4,'TIME REPORT'!$E$6:$E$37,$B12)/60) | M12: =IF($B12="","",SUMIFS('TIME REPORT'!$N$6:$N$37,'TIME REPORT'!$A$6:$A$37,M$4,'TIME REPORT'!$E$6:$E$37,$B12)+SUMIFS('TIME REPORT'!$P$6:$P$37,'TIME REPORT'!$A$6:$A$37,M$4,'TIME REPORT'!$E$6:$E$37,$B12)/60) | N12: =IF($B12="","",SUMIFS('TIME REPORT'!$N$6:$N$37,'TIME REPORT'!$A$6:$A$37,N$4,'TIME REPORT'!$E$6:$E$37,$B12)+SUMIFS('TIME REPORT'!$P$6:$P$37,'TIME REPORT'!$A$6:$A$37,N$4,'TIME REPORT'!$E$6:$E$37,$B12)/60) | ... AK12: =IF($B12="","",SUMIFS('TIME REPORT'!$N$6:$N$37,'TIME REPORT'!$A$6:$A$37,AK$4,'TIME REPORT'!$E$6:$E$37,$B12)+SUMIFS('TIME REPORT'!$P$6:$P$37,'TIME REPORT'!$A$6:$A$37,AK$4,'TIME REPORT'!$E$6:$E$37,$B12)/60) | AL12: =SUM(G12:AK12) -> 0
A13: 8 | B13: {=IFERROR(INDEX(_xlfn._xlws.FILTER(ClientCodeList,COUNTIF('TIME REPORT'!$E$6:$E$37,ClientCodeList)>0),ROWS($B$6:B13)),"")} | D13: {=IF($B13="","",IFERROR(INDEX('TIME REPORT'!$H$6:$H$37,MATCH(1,('TIME REPORT'!$E$6:$E$37=$B13)*('TIME REPORT'!$H$6:$H$37<>""),0)),""))} | G13: =IF($B13="","",SUMIFS('TIME REPORT'!$N$6:$N$37,'TIME REPORT'!$A$6:$A$37,G$4,'TIME REPORT'!$E$6:$E$37,$B13)+SUMIFS('TIME REPORT'!$P$6:$P$37,'TIME REPORT'!$A$6:$A$37,G$4,'TIME REPORT'!$E$6:$E$37,$B13)/60) | H13: =IF($B13="","",SUMIFS('TIME REPORT'!$N$6:$N$37,'TIME REPORT'!$A$6:$A$37,H$4,'TIME REPORT'!$E$6:$E$37,$B13)+SUMIFS('TIME REPORT'!$P$6:$P$37,'TIME REPORT'!$A$6:$A$37,H$4,'TIME REPORT'!$E$6:$E$37,$B13)/60) | I13: =IF($B13="","",SUMIFS('TIME REPORT'!$N$6:$N$37,'TIME REPORT'!$A$6:$A$37,I$4,'TIME REPORT'!$E$6:$E$37,$B13)+SUMIFS('TIME REPORT'!$P$6:$P$37,'TIME REPORT'!$A$6:$A$37,I$4,'TIME REPORT'!$E$6:$E$37,$B13)/60) | J13: =IF($B13="","",SUMIFS('TIME REPORT'!$N$6:$N$37,'TIME REPORT'!$A$6:$A$37,J$4,'TIME REPORT'!$E$6:$E$37,$B13)+SUMIFS('TIME REPORT'!$P$6:$P$37,'TIME REPORT'!$A$6:$A$37,J$4,'TIME REPORT'!$E$6:$E$37,$B13)/60) | K13: =IF($B13="","",SUMIFS('TIME REPORT'!$N$6:$N$37,'TIME REPORT'!$A$6:$A$37,K$4,'TIME REPORT'!$E$6:$E$37,$B13)+SUMIFS('TIME REPORT'!$P$6:$P$37,'TIME REPORT'!$A$6:$A$37,K$4,'TIME REPORT'!$E$6:$E$37,$B13)/60) | L13: =IF($B13="","",SUMIFS('TIME REPORT'!$N$6:$N$37,'TIME REPORT'!$A$6:$A$37,L$4,'TIME REPORT'!$E$6:$E$37,$B13)+SUMIFS('TIME REPORT'!$P$6:$P$37,'TIME REPORT'!$A$6:$A$37,L$4,'TIME REPORT'!$E$6:$E$37,$B13)/60) | M13: =IF($B13="","",SUMIFS('TIME REPORT'!$N$6:$N$37,'TIME REPORT'!$A$6:$A$37,M$4,'TIME REPORT'!$E$6:$E$37,$B13)+SUMIFS('TIME REPORT'!$P$6:$P$37,'TIME REPORT'!$A$6:$A$37,M$4,'TIME REPORT'!$E$6:$E$37,$B13)/60) | N13: =IF($B13="","",SUMIFS('TIME REPORT'!$N$6:$N$37,'TIME REPORT'!$A$6:$A$37,N$4,'TIME REPORT'!$E$6:$E$37,$B13)+SUMIFS('TIME REPORT'!$P$6:$P$37,'TIME REPORT'!$A$6:$A$37,N$4,'TIME REPORT'!$E$6:$E$37,$B13)/60) | ... AK13: =IF($B13="","",SUMIFS('TIME REPORT'!$N$6:$N$37,'TIME REPORT'!$A$6:$A$37,AK$4,'TIME REPORT'!$E$6:$E$37,$B13)+SUMIFS('TIME REPORT'!$P$6:$P$37,'TIME REPORT'!$A$6:$A$37,AK$4,'TIME REPORT'!$E$6:$E$37,$B13)/60) | AL13: =SUM(G13:AK13) -> 0
A14: 9 | B14: {=IFERROR(INDEX(_xlfn._xlws.FILTER(ClientCodeList,COUNTIF('TIME REPORT'!$E$6:$E$37,ClientCodeList)>0),ROWS($B$6:B14)),"")} | D14: {=IF($B14="","",IFERROR(INDEX('TIME REPORT'!$H$6:$H$37,MATCH(1,('TIME REPORT'!$E$6:$E$37=$B14)*('TIME REPORT'!$H$6:$H$37<>""),0)),""))} | G14: =IF($B14="","",SUMIFS('TIME REPORT'!$N$6:$N$37,'TIME REPORT'!$A$6:$A$37,G$4,'TIME REPORT'!$E$6:$E$37,$B14)+SUMIFS('TIME REPORT'!$P$6:$P$37,'TIME REPORT'!$A$6:$A$37,G$4,'TIME REPORT'!$E$6:$E$37,$B14)/60) | H14: =IF($B14="","",SUMIFS('TIME REPORT'!$N$6:$N$37,'TIME REPORT'!$A$6:$A$37,H$4,'TIME REPORT'!$E$6:$E$37,$B14)+SUMIFS('TIME REPORT'!$P$6:$P$37,'TIME REPORT'!$A$6:$A$37,H$4,'TIME REPORT'!$E$6:$E$37,$B14)/60) | I14: =IF($B14="","",SUMIFS('TIME REPORT'!$N$6:$N$37,'TIME REPORT'!$A$6:$A$37,I$4,'TIME REPORT'!$E$6:$E$37,$B14)+SUMIFS('TIME REPORT'!$P$6:$P$37,'TIME REPORT'!$A$6:$A$37,I$4,'TIME REPORT'!$E$6:$E$37,$B14)/60) | J14: =IF($B14="","",SUMIFS('TIME REPORT'!$N$6:$N$37,'TIME REPORT'!$A$6:$A$37,J$4,'TIME REPORT'!$E$6:$E$37,$B14)+SUMIFS('TIME REPORT'!$P$6:$P$37,'TIME REPORT'!$A$6:$A$37,J$4,'TIME REPORT'!$E$6:$E$37,$B14)/60) | K14: =IF($B14="","",SUMIFS('TIME REPORT'!$N$6:$N$37,'TIME REPORT'!$A$6:$A$37,K$4,'TIME REPORT'!$E$6:$E$37,$B14)+SUMIFS('TIME REPORT'!$P$6:$P$37,'TIME REPORT'!$A$6:$A$37,K$4,'TIME REPORT'!$E$6:$E$37,$B14)/60) | L14: =IF($B14="","",SUMIFS('TIME REPORT'!$N$6:$N$37,'TIME REPORT'!$A$6:$A$37,L$4,'TIME REPORT'!$E$6:$E$37,$B14)+SUMIFS('TIME REPORT'!$P$6:$P$37,'TIME REPORT'!$A$6:$A$37,L$4,'TIME REPORT'!$E$6:$E$37,$B14)/60) | M14: =IF($B14="","",SUMIFS('TIME REPORT'!$N$6:$N$37,'TIME REPORT'!$A$6:$A$37,M$4,'TIME REPORT'!$E$6:$E$37,$B14)+SUMIFS('TIME REPORT'!$P$6:$P$37,'TIME REPORT'!$A$6:$A$37,M$4,'TIME REPORT'!$E$6:$E$37,$B14)/60) | N14: =IF($B14="","",SUMIFS('TIME REPORT'!$N$6:$N$37,'TIME REPORT'!$A$6:$A$37,N$4,'TIME REPORT'!$E$6:$E$37,$B14)+SUMIFS('TIME REPORT'!$P$6:$P$37,'TIME REPORT'!$A$6:$A$37,N$4,'TIME REPORT'!$E$6:$E$37,$B14)/60) | ... AK14: =IF($B14="","",SUMIFS('TIME REPORT'!$N$6:$N$37,'TIME REPORT'!$A$6:$A$37,AK$4,'TIME REPORT'!$E$6:$E$37,$B14)+SUMIFS('TIME REPORT'!$P$6:$P$37,'TIME REPORT'!$A$6:$A$37,AK$4,'TIME REPORT'!$E$6:$E$37,$B14)/60) | AL14: =SUM(G14:AK14) -> 0
A15: 10 | B15: {=IFERROR(INDEX(_xlfn._xlws.FILTER(ClientCodeList,COUNTIF('TIME REPORT'!$E$6:$E$37,ClientCodeList)>0),ROWS($B$6:B15)),"")} | D15: {=IF($B15="","",IFERROR(INDEX('TIME REPORT'!$H$6:$H$37,MATCH(1,('TIME REPORT'!$E$6:$E$37=$B15)*('TIME REPORT'!$H$6:$H$37<>""),0)),""))} | G15: =IF($B15="","",SUMIFS('TIME REPORT'!$N$6:$N$37,'TIME REPORT'!$A$6:$A$37,G$4,'TIME REPORT'!$E$6:$E$37,$B15)+SUMIFS('TIME REPORT'!$P$6:$P$37,'TIME REPORT'!$A$6:$A$37,G$4,'TIME REPORT'!$E$6:$E$37,$B15)/60) | H15: =IF($B15="","",SUMIFS('TIME REPORT'!$N$6:$N$37,'TIME REPORT'!$A$6:$A$37,H$4,'TIME REPORT'!$E$6:$E$37,$B15)+SUMIFS('TIME REPORT'!$P$6:$P$37,'TIME REPORT'!$A$6:$A$37,H$4,'TIME REPORT'!$E$6:$E$37,$B15)/60) | I15: =IF($B15="","",SUMIFS('TIME REPORT'!$N$6:$N$37,'TIME REPORT'!$A$6:$A$37,I$4,'TIME REPORT'!$E$6:$E$37,$B15)+SUMIFS('TIME REPORT'!$P$6:$P$37,'TIME REPORT'!$A$6:$A$37,I$4,'TIME REPORT'!$E$6:$E$37,$B15)/60) | J15: =IF($B15="","",SUMIFS('TIME REPORT'!$N$6:$N$37,'TIME REPORT'!$A$6:$A$37,J$4,'TIME REPORT'!$E$6:$E$37,$B15)+SUMIFS('TIME REPORT'!$P$6:$P$37,'TIME REPORT'!$A$6:$A$37,J$4,'TIME REPORT'!$E$6:$E$37,$B15)/60) | K15: =IF($B15="","",SUMIFS('TIME REPORT'!$N$6:$N$37,'TIME REPORT'!$A$6:$A$37,K$4,'TIME REPORT'!$E$6:$E$37,$B15)+SUMIFS('TIME REPORT'!$P$6:$P$37,'TIME REPORT'!$A$6:$A$37,K$4,'TIME REPORT'!$E$6:$E$37,$B15)/60) | L15: =IF($B15="","",SUMIFS('TIME REPORT'!$N$6:$N$37,'TIME REPORT'!$A$6:$A$37,L$4,'TIME REPORT'!$E$6:$E$37,$B15)+SUMIFS('TIME REPORT'!$P$6:$P$37,'TIME REPORT'!$A$6:$A$37,L$4,'TIME REPORT'!$E$6:$E$37,$B15)/60) | M15: =IF($B15="","",SUMIFS('TIME REPORT'!$N$6:$N$37,'TIME REPORT'!$A$6:$A$37,M$4,'TIME REPORT'!$E$6:$E$37,$B15)+SUMIFS('TIME REPORT'!$P$6:$P$37,'TIME REPORT'!$A$6:$A$37,M$4,'TIME REPORT'!$E$6:$E$37,$B15)/60) | N15: =IF($B15="","",SUMIFS('TIME REPORT'!$N$6:$N$37,'TIME REPORT'!$A$6:$A$37,N$4,'TIME REPORT'!$E$6:$E$37,$B15)+SUMIFS('TIME REPORT'!$P$6:$P$37,'TIME REPORT'!$A$6:$A$37,N$4,'TIME REPORT'!$E$6:$E$37,$B15)/60) | ... AK15: =IF($B15="","",SUMIFS('TIME REPORT'!$N$6:$N$37,'TIME REPORT'!$A$6:$A$37,AK$4,'TIME REPORT'!$E$6:$E$37,$B15)+SUMIFS('TIME REPORT'!$P$6:$P$37,'TIME REPORT'!$A$6:$A$37,AK$4,'TIME REPORT'!$E$6:$E$37,$B15)/60) | AL15: =SUM(G15:AK15) -> 0
A16: 11 | B16: {=IFERROR(INDEX(_xlfn._xlws.FILTER(ClientCodeList,COUNTIF('TIME REPORT'!$E$6:$E$37,ClientCodeList)>0),ROWS($B$6:B16)),"")} | D16: {=IF($B16="","",IFERROR(INDEX('TIME REPORT'!$H$6:$H$37,MATCH(1,('TIME REPORT'!$E$6:$E$37=$B16)*('TIME REPORT'!$H$6:$H$37<>""),0)),""))} | G16: =IF($B16="","",SUMIFS('TIME REPORT'!$N$6:$N$37,'TIME REPORT'!$A$6:$A$37,G$4,'TIME REPORT'!$E$6:$E$37,$B16)+SUMIFS('TIME REPORT'!$P$6:$P$37,'TIME REPORT'!$A$6:$A$37,G$4,'TIME REPORT'!$E$6:$E$37,$B16)/60) | H16: =IF($B16="","",SUMIFS('TIME REPORT'!$N$6:$N$37,'TIME REPORT'!$A$6:$A$37,H$4,'TIME REPORT'!$E$6:$E$37,$B16)+SUMIFS('TIME REPORT'!$P$6:$P$37,'TIME REPORT'!$A$6:$A$37,H$4,'TIME REPORT'!$E$6:$E$37,$B16)/60) | I16: =IF($B16="","",SUMIFS('TIME REPORT'!$N$6:$N$37,'TIME REPORT'!$A$6:$A$37,I$4,'TIME REPORT'!$E$6:$E$37,$B16)+SUMIFS('TIME REPORT'!$P$6:$P$37,'TIME REPORT'!$A$6:$A$37,I$4,'TIME REPORT'!$E$6:$E$37,$B16)/60) | J16: =IF($B16="","",SUMIFS('TIME REPORT'!$N$6:$N$37,'TIME REPORT'!$A$6:$A$37,J$4,'TIME REPORT'!$E$6:$E$37,$B16)+SUMIFS('TIME REPORT'!$P$6:$P$37,'TIME REPORT'!$A$6:$A$37,J$4,'TIME REPORT'!$E$6:$E$37,$B16)/60) | K16: =IF($B16="","",SUMIFS('TIME REPORT'!$N$6:$N$37,'TIME REPORT'!$A$6:$A$37,K$4,'TIME REPORT'!$E$6:$E$37,$B16)+SUMIFS('TIME REPORT'!$P$6:$P$37,'TIME REPORT'!$A$6:$A$37,K$4,'TIME REPORT'!$E$6:$E$37,$B16)/60) | L16: =IF($B16="","",SUMIFS('TIME REPORT'!$N$6:$N$37,'TIME REPORT'!$A$6:$A$37,L$4,'TIME REPORT'!$E$6:$E$37,$B16)+SUMIFS('TIME REPORT'!$P$6:$P$37,'TIME REPORT'!$A$6:$A$37,L$4,'TIME REPORT'!$E$6:$E$37,$B16)/60) | M16: =IF($B16="","",SUMIFS('TIME REPORT'!$N$6:$N$37,'TIME REPORT'!$A$6:$A$37,M$4,'TIME REPORT'!$E$6:$E$37,$B16)+SUMIFS('TIME REPORT'!$P$6:$P$37,'TIME REPORT'!$A$6:$A$37,M$4,'TIME REPORT'!$E$6:$E$37,$B16)/60) | N16: =IF($B16="","",SUMIFS('TIME REPORT'!$N$6:$N$37,'TIME REPORT'!$A$6:$A$37,N$4,'TIME REPORT'!$E$6:$E$37,$B16)+SUMIFS('TIME REPORT'!$P$6:$P$37,'TIME REPORT'!$A$6:$A$37,N$4,'TIME REPORT'!$E$6:$E$37,$B16)/60) | ... AK16: =IF($B16="","",SUMIFS('TIME REPORT'!$N$6:$N$37,'TIME REPORT'!$A$6:$A$37,AK$4,'TIME REPORT'!$E$6:$E$37,$B16)+SUMIFS('TIME REPORT'!$P$6:$P$37,'TIME REPORT'!$A$6:$A$37,AK$4,'TIME REPORT'!$E$6:$E$37,$B16)/60) | AL16: =SUM(G16:AK16) -> 0
A17: 12 | B17: {=IFERROR(INDEX(_xlfn._xlws.FILTER(ClientCodeList,COUNTIF('TIME REPORT'!$E$6:$E$37,ClientCodeList)>0),ROWS($B$6:B17)),"")} | D17: {=IF($B17="","",IFERROR(INDEX('TIME REPORT'!$H$6:$H$37,MATCH(1,('TIME REPORT'!$E$6:$E$37=$B17)*('TIME REPORT'!$H$6:$H$37<>""),0)),""))} | G17: =IF($B17="","",SUMIFS('TIME REPORT'!$N$6:$N$37,'TIME REPORT'!$A$6:$A$37,G$4,'TIME REPORT'!$E$6:$E$37,$B17)+SUMIFS('TIME REPORT'!$P$6:$P$37,'TIME REPORT'!$A$6:$A$37,G$4,'TIME REPORT'!$E$6:$E$37,$B17)/60) | H17: =IF($B17="","",SUMIFS('TIME REPORT'!$N$6:$N$37,'TIME REPORT'!$A$6:$A$37,H$4,'TIME REPORT'!$E$6:$E$37,$B17)+SUMIFS('TIME REPORT'!$P$6:$P$37,'TIME REPORT'!$A$6:$A$37,H$4,'TIME REPORT'!$E$6:$E$37,$B17)/60) | I17: =IF($B17="","",SUMIFS('TIME REPORT'!$N$6:$N$37,'TIME REPORT'!$A$6:$A$37,I$4,'TIME REPORT'!$E$6:$E$37,$B17)+SUMIFS('TIME REPORT'!$P$6:$P$37,'TIME REPORT'!$A$6:$A$37,I$4,'TIME REPORT'!$E$6:$E$37,$B17)/60) | J17: =IF($B17="","",SUMIFS('TIME REPORT'!$N$6:$N$37,'TIME REPORT'!$A$6:$A$37,J$4,'TIME REPORT'!$E$6:$E$37,$B17)+SUMIFS('TIME REPORT'!$P$6:$P$37,'TIME REPORT'!$A$6:$A$37,J$4,'TIME REPORT'!$E$6:$E$37,$B17)/60) | K17: =IF($B17="","",SUMIFS('TIME REPORT'!$N$6:$N$37,'TIME REPORT'!$A$6:$A$37,K$4,'TIME REPORT'!$E$6:$E$37,$B17)+SUMIFS('TIME REPORT'!$P$6:$P$37,'TIME REPORT'!$A$6:$A$37,K$4,'TIME REPORT'!$E$6:$E$37,$B17)/60) | L17: =IF($B17="","",SUMIFS('TIME REPORT'!$N$6:$N$37,'TIME REPORT'!$A$6:$A$37,L$4,'TIME REPORT'!$E$6:$E$37,$B17)+SUMIFS('TIME REPORT'!$P$6:$P$37,'TIME REPORT'!$A$6:$A$37,L$4,'TIME REPORT'!$E$6:$E$37,$B17)/60) | M17: =IF($B17="","",SUMIFS('TIME REPORT'!$N$6:$N$37,'TIME REPORT'!$A$6:$A$37,M$4,'TIME REPORT'!$E$6:$E$37,$B17)+SUMIFS('TIME REPORT'!$P$6:$P$37,'TIME REPORT'!$A$6:$A$37,M$4,'TIME REPORT'!$E$6:$E$37,$B17)/60) | N17: =IF($B17="","",SUMIFS('TIME REPORT'!$N$6:$N$37,'TIME REPORT'!$A$6:$A$37,N$4,'TIME REPORT'!$E$6:$E$37,$B17)+SUMIFS('TIME REPORT'!$P$6:$P$37,'TIME REPORT'!$A$6:$A$37,N$4,'TIME REPORT'!$E$6:$E$37,$B17)/60) | ... AK17: =IF($B17="","",SUMIFS('TIME REPORT'!$N$6:$N$37,'TIME REPORT'!$A$6:$A$37,AK$4,'TIME REPORT'!$E$6:$E$37,$B17)+SUMIFS('TIME REPORT'!$P$6:$P$37,'TIME REPORT'!$A$6:$A$37,AK$4,'TIME REPORT'!$E$6:$E$37,$B17)/60) | AL17: =SUM(G17:AK17) -> 0
... A21: 16 | B21: {=IFERROR(INDEX(_xlfn._xlws.FILTER(ClientCodeList,COUNTIF('TIME REPORT'!$E$6:$E$37,ClientCodeList)>0),ROWS($B$6:B21)),"")} | D21: {=IF($B21="","",IFERROR(INDEX('TIME REPORT'!$H$6:$H$37,MATCH(1,('TIME REPORT'!$E$6:$E$37=$B21)*('TIME REPORT'!$H$6:$H$37<>""),0)),""))} | G21: =IF($B21="","",SUMIFS('TIME REPORT'!$N$6:$N$37,'TIME REPORT'!$A$6:$A$37,G$4,'TIME REPORT'!$E$6:$E$37,$B21)+SUMIFS('TIME REPORT'!$P$6:$P$37,'TIME REPORT'!$A$6:$A$37,G$4,'TIME REPORT'!$E$6:$E$37,$B21)/60) | H21: =IF($B21="","",SUMIFS('TIME REPORT'!$N$6:$N$37,'TIME REPORT'!$A$6:$A$37,H$4,'TIME REPORT'!$E$6:$E$37,$B21)+SUMIFS('TIME REPORT'!$P$6:$P$37,'TIME REPORT'!$A$6:$A$37,H$4,'TIME REPORT'!$E$6:$E$37,$B21)/60) | I21: =IF($B21="","",SUMIFS('TIME REPORT'!$N$6:$N$37,'TIME REPORT'!$A$6:$A$37,I$4,'TIME REPORT'!$E$6:$E$37,$B21)+SUMIFS('TIME REPORT'!$P$6:$P$37,'TIME REPORT'!$A$6:$A$37,I$4,'TIME REPORT'!$E$6:$E$37,$B21)/60) | J21: =IF($B21="","",SUMIFS('TIME REPORT'!$N$6:$N$37,'TIME REPORT'!$A$6:$A$37,J$4,'TIME REPORT'!$E$6:$E$37,$B21)+SUMIFS('TIME REPORT'!$P$6:$P$37,'TIME REPORT'!$A$6:$A$37,J$4,'TIME REPORT'!$E$6:$E$37,$B21)/60) | K21: =IF($B21="","",SUMIFS('TIME REPORT'!$N$6:$N$37,'TIME REPORT'!$A$6:$A$37,K$4,'TIME REPORT'!$E$6:$E$37,$B21)+SUMIFS('TIME REPORT'!$P$6:$P$37,'TIME REPORT'!$A$6:$A$37,K$4,'TIME REPORT'!$E$6:$E$37,$B21)/60) | L21: =IF($B21="","",SUMIFS('TIME REPORT'!$N$6:$N$37,'TIME REPORT'!$A$6:$A$37,L$4,'TIME REPORT'!$E$6:$E$37,$B21)+SUMIFS('TIME REPORT'!$P$6:$P$37,'TIME REPORT'!$A$6:$A$37,L$4,'TIME REPORT'!$E$6:$E$37,$B21)/60) | M21: =IF($B21="","",SUMIFS('TIME REPORT'!$N$6:$N$37,'TIME REPORT'!$A$6:$A$37,M$4,'TIME REPORT'!$E$6:$E$37,$B21)+SUMIFS('TIME REPORT'!$P$6:$P$37,'TIME REPORT'!$A$6:$A$37,M$4,'TIME REPORT'!$E$6:$E$37,$B21)/60) | N21: =IF($B21="","",SUMIFS('TIME REPORT'!$N$6:$N$37,'TIME REPORT'!$A$6:$A$37,N$4,'TIME REPORT'!$E$6:$E$37,$B21)+SUMIFS('TIME REPORT'!$P$6:$P$37,'TIME REPORT'!$A$6:$A$37,N$4,'TIME REPORT'!$E$6:$E$37,$B21)/60) | ... AK21: =IF($B21="","",SUMIFS('TIME REPORT'!$N$6:$N$37,'TIME REPORT'!$A$6:$A$37,AK$4,'TIME REPORT'!$E$6:$E$37,$B21)+SUMIFS('TIME REPORT'!$P$6:$P$37,'TIME REPORT'!$A$6:$A$37,AK$4,'TIME REPORT'!$E$6:$E$37,$B21)/60) | AL21: =SUM(G21:AK21) -> 0
A22: TOTAL CHARGE-( A ) | G22: =SUM(G6:G21) -> 0 | H22: =SUM(H6:H21) -> 0 | I22: =SUM(I6:I21) -> 0 | J22: =SUM(J6:J21) -> 0 | K22: =SUM(K6:K21) -> 0 | L22: =SUM(L6:L21) -> 0 | M22: =SUM(M6:M21) -> 0 | N22: =SUM(N6:N21) -> 0 | ... AL22: =SUM(AL6:AL21) -> 0
A23: NON CHARGE
A24: 1. OFFICE (FIRM'S WORK) | G24: =IF("OFFICE"="","",SUMIFS('TIME REPORT'!$N$6:$N$37,'TIME REPORT'!$A$6:$A$37,G$4,'TIME REPORT'!$E$6:$E$37,"OFFICE")+SUMIFS('TIME REPORT'!$P$6:$P$37,'TIME REPORT'!$A$6:$A$37,G$4,'TIME REPORT'!$E$6:$E$37,"OFFICE")/60) -> 0 | H24: =IF("OFFICE"="","",SUMIFS('TIME REPORT'!$N$6:$N$37,'TIME REPORT'!$A$6:$A$37,H$4,'TIME REPORT'!$E$6:$E$37,"OFFICE")+SUMIFS('TIME REPORT'!$P$6:$P$37,'TIME REPORT'!$A$6:$A$37,H$4,'TIME REPORT'!$E$6:$E$37,"OFFICE")/60) -> 0 | I24: =IF("OFFICE"="","",SUMIFS('TIME REPORT'!$N$6:$N$37,'TIME REPORT'!$A$6:$A$37,I$4,'TIME REPORT'!$E$6:$E$37,"OFFICE")+SUMIFS('TIME REPORT'!$P$6:$P$37,'TIME REPORT'!$A$6:$A$37,I$4,'TIME REPORT'!$E$6:$E$37,"OFFICE")/60) -> 0 | J24: =IF("OFFICE"="","",SUMIFS('TIME REPORT'!$N$6:$N$37,'TIME REPORT'!$A$6:$A$37,J$4,'TIME REPORT'!$E$6:$E$37,"OFFICE")+SUMIFS('TIME REPORT'!$P$6:$P$37,'TIME REPORT'!$A$6:$A$37,J$4,'TIME REPORT'!$E$6:$E$37,"OFFICE")/60) -> 0 | K24: =IF("OFFICE"="","",SUMIFS('TIME REPORT'!$N$6:$N$37,'TIME REPORT'!$A$6:$A$37,K$4,'TIME REPORT'!$E$6:$E$37,"OFFICE")+SUMIFS('TIME REPORT'!$P$6:$P$37,'TIME REPORT'!$A$6:$A$37,K$4,'TIME REPORT'!$E$6:$E$37,"OFFICE")/60) -> 0 | L24: =IF("OFFICE"="","",SUMIFS('TIME REPORT'!$N$6:$N$37,'TIME REPORT'!$A$6:$A$37,L$4,'TIME REPORT'!$E$6:$E$37,"OFFICE")+SUMIFS('TIME REPORT'!$P$6:$P$37,'TIME REPORT'!$A$6:$A$37,L$4,'TIME REPORT'!$E$6:$E$37,"OFFICE")/60) -> 0 | M24: =IF("OFFICE"="","",SUMIFS('TIME REPORT'!$N$6:$N$37,'TIME REPORT'!$A$6:$A$37,M$4,'TIME REPORT'!$E$6:$E$37,"OFFICE")+SUMIFS('TIME REPORT'!$P$6:$P$37,'TIME REPORT'!$A$6:$A$37,M$4,'TIME REPORT'!$E$6:$E$37,"OFFICE")/60) -> 0 | N24: =IF("OFFICE"="","",SUMIFS('TIME REPORT'!$N$6:$N$37,'TIME REPORT'!$A$6:$A$37,N$4,'TIME REPORT'!$E$6:$E$37,"OFFICE")+SUMIFS('TIME REPORT'!$P$6:$P$37,'TIME REPORT'!$A$6:$A$37,N$4,'TIME REPORT'!$E$6:$E$37,"OFFICE")/60) -> 0 | ... AK24: =IF("OFFICE"="","",SUMIFS('TIME REPORT'!$N$6:$N$37,'TIME REPORT'!$A$6:$A$37,AK$4,'TIME REPORT'!$E$6:$E$37,"OFFICE")+SUMIFS('TIME REPORT'!$P$6:$P$37,'TIME REPORT'!$A$6:$A$37,AK$4,'TIME REPORT'!$E$6:$E$37,"OFFICE")/60) -> 0 | AL24: =SUM(G24:AK24) -> 0
A25: 2. ลาป่วย (SICK) | G25: =IF("ลาป่วย"="","",SUMIFS('TIME REPORT'!$N$6:$N$37,'TIME REPORT'!$A$6:$A$37,G$4,'TIME REPORT'!$E$6:$E$37,"ลาป่วย")+SUMIFS('TIME REPORT'!$P$6:$P$37,'TIME REPORT'!$A$6:$A$37,G$4,'TIME REPORT'!$E$6:$E$37,"ลาป่วย")/60) -> 0 | H25: =IF("ลาป่วย"="","",SUMIFS('TIME REPORT'!$N$6:$N$37,'TIME REPORT'!$A$6:$A$37,H$4,'TIME REPORT'!$E$6:$E$37,"ลาป่วย")+SUMIFS('TIME REPORT'!$P$6:$P$37,'TIME REPORT'!$A$6:$A$37,H$4,'TIME REPORT'!$E$6:$E$37,"ลาป่วย")/60) -> 0 | I25: =IF("ลาป่วย"="","",SUMIFS('TIME REPORT'!$N$6:$N$37,'TIME REPORT'!$A$6:$A$37,I$4,'TIME REPORT'!$E$6:$E$37,"ลาป่วย")+SUMIFS('TIME REPORT'!$P$6:$P$37,'TIME REPORT'!$A$6:$A$37,I$4,'TIME REPORT'!$E$6:$E$37,"ลาป่วย")/60) -> 0 | J25: =IF("ลาป่วย"="","",SUMIFS('TIME REPORT'!$N$6:$N$37,'TIME REPORT'!$A$6:$A$37,J$4,'TIME REPORT'!$E$6:$E$37,"ลาป่วย")+SUMIFS('TIME REPORT'!$P$6:$P$37,'TIME REPORT'!$A$6:$A$37,J$4,'TIME REPORT'!$E$6:$E$37,"ลาป่วย")/60) -> 0 | K25: =IF("ลาป่วย"="","",SUMIFS('TIME REPORT'!$N$6:$N$37,'TIME REPORT'!$A$6:$A$37,K$4,'TIME REPORT'!$E$6:$E$37,"ลาป่วย")+SUMIFS('TIME REPORT'!$P$6:$P$37,'TIME REPORT'!$A$6:$A$37,K$4,'TIME REPORT'!$E$6:$E$37,"ลาป่วย")/60) -> 0 | L25: =IF("ลาป่วย"="","",SUMIFS('TIME REPORT'!$N$6:$N$37,'TIME REPORT'!$A$6:$A$37,L$4,'TIME REPORT'!$E$6:$E$37,"ลาป่วย")+SUMIFS('TIME REPORT'!$P$6:$P$37,'TIME REPORT'!$A$6:$A$37,L$4,'TIME REPORT'!$E$6:$E$37,"ลาป่วย")/60) -> 0 | M25: =IF("ลาป่วย"="","",SUMIFS('TIME REPORT'!$N$6:$N$37,'TIME REPORT'!$A$6:$A$37,M$4,'TIME REPORT'!$E$6:$E$37,"ลาป่วย")+SUMIFS('TIME REPORT'!$P$6:$P$37,'TIME REPORT'!$A$6:$A$37,M$4,'TIME REPORT'!$E$6:$E$37,"ลาป่วย")/60) -> 0 | N25: =IF("ลาป่วย"="","",SUMIFS('TIME REPORT'!$N$6:$N$37,'TIME REPORT'!$A$6:$A$37,N$4,'TIME REPORT'!$E$6:$E$37,"ลาป่วย")+SUMIFS('TIME REPORT'!$P$6:$P$37,'TIME REPORT'!$A$6:$A$37,N$4,'TIME REPORT'!$E$6:$E$37,"ลาป่วย")/60) -> 0 | ... AK25: =IF("ลาป่วย"="","",SUMIFS('TIME REPORT'!$N$6:$N$37,'TIME REPORT'!$A$6:$A$37,AK$4,'TIME REPORT'!$E$6:$E$37,"ลาป่วย")+SUMIFS('TIME REPORT'!$P$6:$P$37,'TIME REPORT'!$A$6:$A$37,AK$4,'TIME REPORT'!$E$6:$E$37,"ลาป่วย")/60) -> 0 | AL25: =SUM(G25:AK25) -> 0
A26: 3. ลาพักร้อน (HOLIDAY) | G26: =IF("ลาพักร้อน"="","",SUMIFS('TIME REPORT'!$N$6:$N$37,'TIME REPORT'!$A$6:$A$37,G$4,'TIME REPORT'!$E$6:$E$37,"ลาพักร้อน")+SUMIFS('TIME REPORT'!$P$6:$P$37,'TIME REPORT'!$A$6:$A$37,G$4,'TIME REPORT'!$E$6:$E$37,"ลาพักร้อน")/60) -> 0 | H26: =IF("ลาพักร้อน"="","",SUMIFS('TIME REPORT'!$N$6:$N$37,'TIME REPORT'!$A$6:$A$37,H$4,'TIME REPORT'!$E$6:$E$37,"ลาพักร้อน")+SUMIFS('TIME REPORT'!$P$6:$P$37,'TIME REPORT'!$A$6:$A$37,H$4,'TIME REPORT'!$E$6:$E$37,"ลาพักร้อน")/60) -> 0 | I26: =IF("ลาพักร้อน"="","",SUMIFS('TIME REPORT'!$N$6:$N$37,'TIME REPORT'!$A$6:$A$37,I$4,'TIME REPORT'!$E$6:$E$37,"ลาพักร้อน")+SUMIFS('TIME REPORT'!$P$6:$P$37,'TIME REPORT'!$A$6:$A$37,I$4,'TIME REPORT'!$E$6:$E$37,"ลาพักร้อน")/60) -> 0 | J26: =IF("ลาพักร้อน"="","",SUMIFS('TIME REPORT'!$N$6:$N$37,'TIME REPORT'!$A$6:$A$37,J$4,'TIME REPORT'!$E$6:$E$37,"ลาพักร้อน")+SUMIFS('TIME REPORT'!$P$6:$P$37,'TIME REPORT'!$A$6:$A$37,J$4,'TIME REPORT'!$E$6:$E$37,"ลาพักร้อน")/60) -> 0 | K26: =IF("ลาพักร้อน"="","",SUMIFS('TIME REPORT'!$N$6:$N$37,'TIME REPORT'!$A$6:$A$37,K$4,'TIME REPORT'!$E$6:$E$37,"ลาพักร้อน")+SUMIFS('TIME REPORT'!$P$6:$P$37,'TIME REPORT'!$A$6:$A$37,K$4,'TIME REPORT'!$E$6:$E$37,"ลาพักร้อน")/60) -> 0 | L26: =IF("ลาพักร้อน"="","",SUMIFS('TIME REPORT'!$N$6:$N$37,'TIME REPORT'!$A$6:$A$37,L$4,'TIME REPORT'!$E$6:$E$37,"ลาพักร้อน")+SUMIFS('TIME REPORT'!$P$6:$P$37,'TIME REPORT'!$A$6:$A$37,L$4,'TIME REPORT'!$E$6:$E$37,"ลาพักร้อน")/60) -> 0 | M26: =IF("ลาพักร้อน"="","",SUMIFS('TIME REPORT'!$N$6:$N$37,'TIME REPORT'!$A$6:$A$37,M$4,'TIME REPORT'!$E$6:$E$37,"ลาพักร้อน")+SUMIFS('TIME REPORT'!$P$6:$P$37,'TIME REPORT'!$A$6:$A$37,M$4,'TIME REPORT'!$E$6:$E$37,"ลาพักร้อน")/60) -> 0 | N26: =IF("ลาพักร้อน"="","",SUMIFS('TIME REPORT'!$N$6:$N$37,'TIME REPORT'!$A$6:$A$37,N$4,'TIME REPORT'!$E$6:$E$37,"ลาพักร้อน")+SUMIFS('TIME REPORT'!$P$6:$P$37,'TIME REPORT'!$A$6:$A$37,N$4,'TIME REPORT'!$E$6:$E$37,"ลาพักร้อน")/60) -> 0 | ... AK26: =IF("ลาพักร้อน"="","",SUMIFS('TIME REPORT'!$N$6:$N$37,'TIME REPORT'!$A$6:$A$37,AK$4,'TIME REPORT'!$E$6:$E$37,"ลาพักร้อน")+SUMIFS('TIME REPORT'!$P$6:$P$37,'TIME REPORT'!$A$6:$A$37,AK$4,'TIME REPORT'!$E$6:$E$37,"ลาพักร้อน")/60) -> 0 | AL26: =SUM(G26:AK26) -> 0
A27: 4. อบรม (TRAINING) | G27: =IF("อบรม"="","",SUMIFS('TIME REPORT'!$N$6:$N$37,'TIME REPORT'!$A$6:$A$37,G$4,'TIME REPORT'!$E$6:$E$37,"อบรม")+SUMIFS('TIME REPORT'!$P$6:$P$37,'TIME REPORT'!$A$6:$A$37,G$4,'TIME REPORT'!$E$6:$E$37,"อบรม")/60) -> 0 | H27: =IF("อบรม"="","",SUMIFS('TIME REPORT'!$N$6:$N$37,'TIME REPORT'!$A$6:$A$37,H$4,'TIME REPORT'!$E$6:$E$37,"อบรม")+SUMIFS('TIME REPORT'!$P$6:$P$37,'TIME REPORT'!$A$6:$A$37,H$4,'TIME REPORT'!$E$6:$E$37,"อบรม")/60) -> 0 | I27: =IF("อบรม"="","",SUMIFS('TIME REPORT'!$N$6:$N$37,'TIME REPORT'!$A$6:$A$37,I$4,'TIME REPORT'!$E$6:$E$37,"อบรม")+SUMIFS('TIME REPORT'!$P$6:$P$37,'TIME REPORT'!$A$6:$A$37,I$4,'TIME REPORT'!$E$6:$E$37,"อบรม")/60) -> 0 | J27: =IF("อบรม"="","",SUMIFS('TIME REPORT'!$N$6:$N$37,'TIME REPORT'!$A$6:$A$37,J$4,'TIME REPORT'!$E$6:$E$37,"อบรม")+SUMIFS('TIME REPORT'!$P$6:$P$37,'TIME REPORT'!$A$6:$A$37,J$4,'TIME REPORT'!$E$6:$E$37,"อบรม")/60) -> 0 | K27: =IF("อบรม"="","",SUMIFS('TIME REPORT'!$N$6:$N$37,'TIME REPORT'!$A$6:$A$37,K$4,'TIME REPORT'!$E$6:$E$37,"อบรม")+SUMIFS('TIME REPORT'!$P$6:$P$37,'TIME REPORT'!$A$6:$A$37,K$4,'TIME REPORT'!$E$6:$E$37,"อบรม")/60) -> 0 | L27: =IF("อบรม"="","",SUMIFS('TIME REPORT'!$N$6:$N$37,'TIME REPORT'!$A$6:$A$37,L$4,'TIME REPORT'!$E$6:$E$37,"อบรม")+SUMIFS('TIME REPORT'!$P$6:$P$37,'TIME REPORT'!$A$6:$A$37,L$4,'TIME REPORT'!$E$6:$E$37,"อบรม")/60) -> 0 | M27: =IF("อบรม"="","",SUMIFS('TIME REPORT'!$N$6:$N$37,'TIME REPORT'!$A$6:$A$37,M$4,'TIME REPORT'!$E$6:$E$37,"อบรม")+SUMIFS('TIME REPORT'!$P$6:$P$37,'TIME REPORT'!$A$6:$A$37,M$4,'TIME REPORT'!$E$6:$E$37,"อบรม")/60) -> 0 | N27: =IF("อบรม"="","",SUMIFS('TIME REPORT'!$N$6:$N$37,'TIME REPORT'!$A$6:$A$37,N$4,'TIME REPORT'!$E$6:$E$37,"อบรม")+SUMIFS('TIME REPORT'!$P$6:$P$37,'TIME REPORT'!$A$6:$A$37,N$4,'TIME REPORT'!$E$6:$E$37,"อบรม")/60) -> 0 | ... AK27: =IF("อบรม"="","",SUMIFS('TIME REPORT'!$N$6:$N$37,'TIME REPORT'!$A$6:$A$37,AK$4,'TIME REPORT'!$E$6:$E$37,"อบรม")+SUMIFS('TIME REPORT'!$P$6:$P$37,'TIME REPORT'!$A$6:$A$37,AK$4,'TIME REPORT'!$E$6:$E$37,"อบรม")/60) -> 0 | AL27: =SUM(G27:AK27) -> 0
A28: 5. ลา OT สะสม (OT ACCUMULATED) | G28: =IF("ลา OT สะสม"="","",SUMIFS('TIME REPORT'!$N$6:$N$37,'TIME REPORT'!$A$6:$A$37,G$4,'TIME REPORT'!$E$6:$E$37,"ลา OT สะสม")+SUMIFS('TIME REPORT'!$P$6:$P$37,'TIME REPORT'!$A$6:$A$37,G$4,'TIME REPORT'!$E$6:$E$37,"ลา OT สะสม")/60) -> 0 | H28: =IF("ลา OT สะสม"="","",SUMIFS('TIME REPORT'!$N$6:$N$37,'TIME REPORT'!$A$6:$A$37,H$4,'TIME REPORT'!$E$6:$E$37,"ลา OT สะสม")+SUMIFS('TIME REPORT'!$P$6:$P$37,'TIME REPORT'!$A$6:$A$37,H$4,'TIME REPORT'!$E$6:$E$37,"ลา OT สะสม")/60) -> 0 | I28: =IF("ลา OT สะสม"="","",SUMIFS('TIME REPORT'!$N$6:$N$37,'TIME REPORT'!$A$6:$A$37,I$4,'TIME REPORT'!$E$6:$E$37,"ลา OT สะสม")+SUMIFS('TIME REPORT'!$P$6:$P$37,'TIME REPORT'!$A$6:$A$37,I$4,'TIME REPORT'!$E$6:$E$37,"ลา OT สะสม")/60) -> 0 | J28: =IF("ลา OT สะสม"="","",SUMIFS('TIME REPORT'!$N$6:$N$37,'TIME REPORT'!$A$6:$A$37,J$4,'TIME REPORT'!$E$6:$E$37,"ลา OT สะสม")+SUMIFS('TIME REPORT'!$P$6:$P$37,'TIME REPORT'!$A$6:$A$37,J$4,'TIME REPORT'!$E$6:$E$37,"ลา OT สะสม")/60) -> 0 | K28: =IF("ลา OT สะสม"="","",SUMIFS('TIME REPORT'!$N$6:$N$37,'TIME REPORT'!$A$6:$A$37,K$4,'TIME REPORT'!$E$6:$E$37,"ลา OT สะสม")+SUMIFS('TIME REPORT'!$P$6:$P$37,'TIME REPORT'!$A$6:$A$37,K$4,'TIME REPORT'!$E$6:$E$37,"ลา OT สะสม")/60) -> 0 | L28: =IF("ลา OT สะสม"="","",SUMIFS('TIME REPORT'!$N$6:$N$37,'TIME REPORT'!$A$6:$A$37,L$4,'TIME REPORT'!$E$6:$E$37,"ลา OT สะสม")+SUMIFS('TIME REPORT'!$P$6:$P$37,'TIME REPORT'!$A$6:$A$37,L$4,'TIME REPORT'!$E$6:$E$37,"ลา OT สะสม")/60) -> 0 | M28: =IF("ลา OT สะสม"="","",SUMIFS('TIME REPORT'!$N$6:$N$37,'TIME REPORT'!$A$6:$A$37,M$4,'TIME REPORT'!$E$6:$E$37,"ลา OT สะสม")+SUMIFS('TIME REPORT'!$P$6:$P$37,'TIME REPORT'!$A$6:$A$37,M$4,'TIME REPORT'!$E$6:$E$37,"ลา OT สะสม")/60) -> 0 | N28: =IF("ลา OT สะสม"="","",SUMIFS('TIME REPORT'!$N$6:$N$37,'TIME REPORT'!$A$6:$A$37,N$4,'TIME REPORT'!$E$6:$E$37,"ลา OT สะสม")+SUMIFS('TIME REPORT'!$P$6:$P$37,'TIME REPORT'!$A$6:$A$37,N$4,'TIME REPORT'!$E$6:$E$37,"ลา OT สะสม")/60) -> 0 | ... AK28: =IF("ลา OT สะสม"="","",SUMIFS('TIME REPORT'!$N$6:$N$37,'TIME REPORT'!$A$6:$A$37,AK$4,'TIME REPORT'!$E$6:$E$37,"ลา OT สะสม")+SUMIFS('TIME REPORT'!$P$6:$P$37,'TIME REPORT'!$A$6:$A$37,AK$4,'TIME REPORT'!$E$6:$E$37,"ลา OT สะสม")/60) -> 0 | AL28: =SUM(G28:AK28) -> 0
A29: 6. ลากิจ (PERSONAL LEAVE) | G29: =IF("ลากิจ"="","",SUMIFS('TIME REPORT'!$N$6:$N$37,'TIME REPORT'!$A$6:$A$37,G$4,'TIME REPORT'!$E$6:$E$37,"ลากิจ")+SUMIFS('TIME REPORT'!$P$6:$P$37,'TIME REPORT'!$A$6:$A$37,G$4,'TIME REPORT'!$E$6:$E$37,"ลากิจ")/60) -> 0 | H29: =IF("ลากิจ"="","",SUMIFS('TIME REPORT'!$N$6:$N$37,'TIME REPORT'!$A$6:$A$37,H$4,'TIME REPORT'!$E$6:$E$37,"ลากิจ")+SUMIFS('TIME REPORT'!$P$6:$P$37,'TIME REPORT'!$A$6:$A$37,H$4,'TIME REPORT'!$E$6:$E$37,"ลากิจ")/60) -> 0 | I29: =IF("ลากิจ"="","",SUMIFS('TIME REPORT'!$N$6:$N$37,'TIME REPORT'!$A$6:$A$37,I$4,'TIME REPORT'!$E$6:$E$37,"ลากิจ")+SUMIFS('TIME REPORT'!$P$6:$P$37,'TIME REPORT'!$A$6:$A$37,I$4,'TIME REPORT'!$E$6:$E$37,"ลากิจ")/60) -> 0 | J29: =IF("ลากิจ"="","",SUMIFS('TIME REPORT'!$N$6:$N$37,'TIME REPORT'!$A$6:$A$37,J$4,'TIME REPORT'!$E$6:$E$37,"ลากิจ")+SUMIFS('TIME REPORT'!$P$6:$P$37,'TIME REPORT'!$A$6:$A$37,J$4,'TIME REPORT'!$E$6:$E$37,"ลากิจ")/60) -> 0 | K29: =IF("ลากิจ"="","",SUMIFS('TIME REPORT'!$N$6:$N$37,'TIME REPORT'!$A$6:$A$37,K$4,'TIME REPORT'!$E$6:$E$37,"ลากิจ")+SUMIFS('TIME REPORT'!$P$6:$P$37,'TIME REPORT'!$A$6:$A$37,K$4,'TIME REPORT'!$E$6:$E$37,"ลากิจ")/60) -> 0 | L29: =IF("ลากิจ"="","",SUMIFS('TIME REPORT'!$N$6:$N$37,'TIME REPORT'!$A$6:$A$37,L$4,'TIME REPORT'!$E$6:$E$37,"ลากิจ")+SUMIFS('TIME REPORT'!$P$6:$P$37,'TIME REPORT'!$A$6:$A$37,L$4,'TIME REPORT'!$E$6:$E$37,"ลากิจ")/60) -> 0 | M29: =IF("ลากิจ"="","",SUMIFS('TIME REPORT'!$N$6:$N$37,'TIME REPORT'!$A$6:$A$37,M$4,'TIME REPORT'!$E$6:$E$37,"ลากิจ")+SUMIFS('TIME REPORT'!$P$6:$P$37,'TIME REPORT'!$A$6:$A$37,M$4,'TIME REPORT'!$E$6:$E$37,"ลากิจ")/60) -> 0 | N29: =IF("ลากิจ"="","",SUMIFS('TIME REPORT'!$N$6:$N$37,'TIME REPORT'!$A$6:$A$37,N$4,'TIME REPORT'!$E$6:$E$37,"ลากิจ")+SUMIFS('TIME REPORT'!$P$6:$P$37,'TIME REPORT'!$A$6:$A$37,N$4,'TIME REPORT'!$E$6:$E$37,"ลากิจ")/60) -> 0 | ... AK29: =IF("ลากิจ"="","",SUMIFS('TIME REPORT'!$N$6:$N$37,'TIME REPORT'!$A$6:$A$37,AK$4,'TIME REPORT'!$E$6:$E$37,"ลากิจ")+SUMIFS('TIME REPORT'!$P$6:$P$37,'TIME REPORT'!$A$6:$A$37,AK$4,'TIME REPORT'!$E$6:$E$37,"ลากิจ")/60) -> 0 | AL29: =SUM(G29:AK29) -> 0
A30: TOTAL NON CHARGE-( B ) | G30: =SUM(G24:G29) -> 0 | H30: =SUM(H24:H29) -> 0 | I30: =SUM(I24:I29) -> 0 | J30: =SUM(J24:J29) -> 0 | K30: =SUM(K24:K29) -> 0 | L30: =SUM(L24:L29) -> 0 | M30: =SUM(M24:M29) -> 0 | N30: =SUM(N24:N29) -> 0 | ... AL30: =SUM(AL24:AL29) -> 0
A31: OVER TIME-( C ) | G31: =IF(COUNTIFS('TIME REPORT'!$A$6:$A$37,G$4,'TIME REPORT'!$Q$6:$Q$37,"O.T.")=0,"",IF(OR(WEEKDAY(DATE(HOLIDAYS!$E$3,HOLIDAYS!$E$2,G$4),2)>=6,COUNTIF(HOLIDAYS!$A$5:$A$199,DATE(HOLIDAYS!$E$3,HOLIDAYS!$E$2,G$4))>0),SUMIFS('TIME REPORT'!$N$6:$N$37,'TIME REPORT'!$A$6:$A$37,G$4)+SUMIFS('TIME REPORT'!$P$6:$P$37,'TIME REPORT'!$A$6:$A$37,G$4)/60,MAX(0,SUMIFS('TIME REPORT'!$N$6:$N$37,'TIME REPORT'!$A$6:$A$37,G$4)+SUMIFS('TIME REPORT'!$P$6:$P$37,'TIME REPORT'!$A$6:$A$37,G$4)/60-$AO$1))) | H31: =IF(COUNTIFS('TIME REPORT'!$A$6:$A$37,H$4,'TIME REPORT'!$Q$6:$Q$37,"O.T.")=0,"",IF(OR(WEEKDAY(DATE(HOLIDAYS!$E$3,HOLIDAYS!$E$2,H$4),2)>=6,COUNTIF(HOLIDAYS!$A$5:$A$199,DATE(HOLIDAYS!$E$3,HOLIDAYS!$E$2,H$4))>0),SUMIFS('TIME REPORT'!$N$6:$N$37,'TIME REPORT'!$A$6:$A$37,H$4)+SUMIFS('TIME REPORT'!$P$6:$P$37,'TIME REPORT'!$A$6:$A$37,H$4)/60,MAX(0,SUMIFS('TIME REPORT'!$N$6:$N$37,'TIME REPORT'!$A$6:$A$37,H$4)+SUMIFS('TIME REPORT'!$P$6:$P$37,'TIME REPORT'!$A$6:$A$37,H$4)/60-$AO$1))) | I31: =IF(COUNTIFS('TIME REPORT'!$A$6:$A$37,I$4,'TIME REPORT'!$Q$6:$Q$37,"O.T.")=0,"",IF(OR(WEEKDAY(DATE(HOLIDAYS!$E$3,HOLIDAYS!$E$2,I$4),2)>=6,COUNTIF(HOLIDAYS!$A$5:$A$199,DATE(HOLIDAYS!$E$3,HOLIDAYS!$E$2,I$4))>0),SUMIFS('TIME REPORT'!$N$6:$N$37,'TIME REPORT'!$A$6:$A$37,I$4)+SUMIFS('TIME REPORT'!$P$6:$P$37,'TIME REPORT'!$A$6:$A$37,I$4)/60,MAX(0,SUMIFS('TIME REPORT'!$N$6:$N$37,'TIME REPORT'!$A$6:$A$37,I$4)+SUMIFS('TIME REPORT'!$P$6:$P$37,'TIME REPORT'!$A$6:$A$37,I$4)/60-$AO$1))) | J31: =IF(COUNTIFS('TIME REPORT'!$A$6:$A$37,J$4,'TIME REPORT'!$Q$6:$Q$37,"O.T.")=0,"",IF(OR(WEEKDAY(DATE(HOLIDAYS!$E$3,HOLIDAYS!$E$2,J$4),2)>=6,COUNTIF(HOLIDAYS!$A$5:$A$199,DATE(HOLIDAYS!$E$3,HOLIDAYS!$E$2,J$4))>0),SUMIFS('TIME REPORT'!$N$6:$N$37,'TIME REPORT'!$A$6:$A$37,J$4)+SUMIFS('TIME REPORT'!$P$6:$P$37,'TIME REPORT'!$A$6:$A$37,J$4)/60,MAX(0,SUMIFS('TIME REPORT'!$N$6:$N$37,'TIME REPORT'!$A$6:$A$37,J$4)+SUMIFS('TIME REPORT'!$P$6:$P$37,'TIME REPORT'!$A$6:$A$37,J$4)/60-$AO$1))) | K31: =IF(COUNTIFS('TIME REPORT'!$A$6:$A$37,K$4,'TIME REPORT'!$Q$6:$Q$37,"O.T.")=0,"",IF(OR(WEEKDAY(DATE(HOLIDAYS!$E$3,HOLIDAYS!$E$2,K$4),2)>=6,COUNTIF(HOLIDAYS!$A$5:$A$199,DATE(HOLIDAYS!$E$3,HOLIDAYS!$E$2,K$4))>0),SUMIFS('TIME REPORT'!$N$6:$N$37,'TIME REPORT'!$A$6:$A$37,K$4)+SUMIFS('TIME REPORT'!$P$6:$P$37,'TIME REPORT'!$A$6:$A$37,K$4)/60,MAX(0,SUMIFS('TIME REPORT'!$N$6:$N$37,'TIME REPORT'!$A$6:$A$37,K$4)+SUMIFS('TIME REPORT'!$P$6:$P$37,'TIME REPORT'!$A$6:$A$37,K$4)/60-$AO$1))) | L31: =IF(COUNTIFS('TIME REPORT'!$A$6:$A$37,L$4,'TIME REPORT'!$Q$6:$Q$37,"O.T.")=0,"",IF(OR(WEEKDAY(DATE(HOLIDAYS!$E$3,HOLIDAYS!$E$2,L$4),2)>=6,COUNTIF(HOLIDAYS!$A$5:$A$199,DATE(HOLIDAYS!$E$3,HOLIDAYS!$E$2,L$4))>0),SUMIFS('TIME REPORT'!$N$6:$N$37,'TIME REPORT'!$A$6:$A$37,L$4)+SUMIFS('TIME REPORT'!$P$6:$P$37,'TIME REPORT'!$A$6:$A$37,L$4)/60,MAX(0,SUMIFS('TIME REPORT'!$N$6:$N$37,'TIME REPORT'!$A$6:$A$37,L$4)+SUMIFS('TIME REPORT'!$P$6:$P$37,'TIME REPORT'!$A$6:$A$37,L$4)/60-$AO$1))) | M31: =IF(COUNTIFS('TIME REPORT'!$A$6:$A$37,M$4,'TIME REPORT'!$Q$6:$Q$37,"O.T.")=0,"",IF(OR(WEEKDAY(DATE(HOLIDAYS!$E$3,HOLIDAYS!$E$2,M$4),2)>=6,COUNTIF(HOLIDAYS!$A$5:$A$199,DATE(HOLIDAYS!$E$3,HOLIDAYS!$E$2,M$4))>0),SUMIFS('TIME REPORT'!$N$6:$N$37,'TIME REPORT'!$A$6:$A$37,M$4)+SUMIFS('TIME REPORT'!$P$6:$P$37,'TIME REPORT'!$A$6:$A$37,M$4)/60,MAX(0,SUMIFS('TIME REPORT'!$N$6:$N$37,'TIME REPORT'!$A$6:$A$37,M$4)+SUMIFS('TIME REPORT'!$P$6:$P$37,'TIME REPORT'!$A$6:$A$37,M$4)/60-$AO$1))) | N31: =IF(COUNTIFS('TIME REPORT'!$A$6:$A$37,N$4,'TIME REPORT'!$Q$6:$Q$37,"O.T.")=0,"",IF(OR(WEEKDAY(DATE(HOLIDAYS!$E$3,HOLIDAYS!$E$2,N$4),2)>=6,COUNTIF(HOLIDAYS!$A$5:$A$199,DATE(HOLIDAYS!$E$3,HOLIDAYS!$E$2,N$4))>0),SUMIFS('TIME REPORT'!$N$6:$N$37,'TIME REPORT'!$A$6:$A$37,N$4)+SUMIFS('TIME REPORT'!$P$6:$P$37,'TIME REPORT'!$A$6:$A$37,N$4)/60,MAX(0,SUMIFS('TIME REPORT'!$N$6:$N$37,'TIME REPORT'!$A$6:$A$37,N$4)+SUMIFS('TIME REPORT'!$P$6:$P$37,'TIME REPORT'!$A$6:$A$37,N$4)/60-$AO$1))) | ... AK31: =IF(COUNTIFS('TIME REPORT'!$A$6:$A$37,AK$4,'TIME REPORT'!$Q$6:$Q$37,"O.T.")=0,"",IF(OR(WEEKDAY(DATE(HOLIDAYS!$E$3,HOLIDAYS!$E$2,AK$4),2)>=6,COUNTIF(HOLIDAYS!$A$5:$A$199,DATE(HOLIDAYS!$E$3,HOLIDAYS!$E$2,AK$4))>0),SUMIFS('TIME REPORT'!$N$6:$N$37,'TIME REPORT'!$A$6:$A$37,AK$4)+SUMIFS('TIME REPORT'!$P$6:$P$37,'TIME REPORT'!$A$6:$A$37,AK$4)/60,MAX(0,SUMIFS('TIME REPORT'!$N$6:$N$37,'TIME REPORT'!$A$6:$A$37,AK$4)+SUMIFS('TIME REPORT'!$P$6:$P$37,'TIME REPORT'!$A$6:$A$37,AK$4)/60-$AO$1))) | AL31: =SUM(G31:AK31) -> 0
A32: EXTRA HOURS-( D ) | G32: =IF(COUNTIFS('TIME REPORT'!$A$6:$A$37,G$4,'TIME REPORT'!$Q$6:$Q$37,"Extra Hours")=0,"",IF(OR(WEEKDAY(DATE(HOLIDAYS!$E$3,HOLIDAYS!$E$2,G$4),2)>=6,COUNTIF(HOLIDAYS!$A$5:$A$199,DATE(HOLIDAYS!$E$3,HOLIDAYS!$E$2,G$4))>0),SUMIFS('TIME REPORT'!$N$6:$N$37,'TIME REPORT'!$A$6:$A$37,G$4)+SUMIFS('TIME REPORT'!$P$6:$P$37,'TIME REPORT'!$A$6:$A$37,G$4)/60,MAX(0,SUMIFS('TIME REPORT'!$N$6:$N$37,'TIME REPORT'!$A$6:$A$37,G$4)+SUMIFS('TIME REPORT'!$P$6:$P$37,'TIME REPORT'!$A$6:$A$37,G$4)/60-$AO$1))) | H32: =IF(COUNTIFS('TIME REPORT'!$A$6:$A$37,H$4,'TIME REPORT'!$Q$6:$Q$37,"Extra Hours")=0,"",IF(OR(WEEKDAY(DATE(HOLIDAYS!$E$3,HOLIDAYS!$E$2,H$4),2)>=6,COUNTIF(HOLIDAYS!$A$5:$A$199,DATE(HOLIDAYS!$E$3,HOLIDAYS!$E$2,H$4))>0),SUMIFS('TIME REPORT'!$N$6:$N$37,'TIME REPORT'!$A$6:$A$37,H$4)+SUMIFS('TIME REPORT'!$P$6:$P$37,'TIME REPORT'!$A$6:$A$37,H$4)/60,MAX(0,SUMIFS('TIME REPORT'!$N$6:$N$37,'TIME REPORT'!$A$6:$A$37,H$4)+SUMIFS('TIME REPORT'!$P$6:$P$37,'TIME REPORT'!$A$6:$A$37,H$4)/60-$AO$1))) | I32: =IF(COUNTIFS('TIME REPORT'!$A$6:$A$37,I$4,'TIME REPORT'!$Q$6:$Q$37,"Extra Hours")=0,"",IF(OR(WEEKDAY(DATE(HOLIDAYS!$E$3,HOLIDAYS!$E$2,I$4),2)>=6,COUNTIF(HOLIDAYS!$A$5:$A$199,DATE(HOLIDAYS!$E$3,HOLIDAYS!$E$2,I$4))>0),SUMIFS('TIME REPORT'!$N$6:$N$37,'TIME REPORT'!$A$6:$A$37,I$4)+SUMIFS('TIME REPORT'!$P$6:$P$37,'TIME REPORT'!$A$6:$A$37,I$4)/60,MAX(0,SUMIFS('TIME REPORT'!$N$6:$N$37,'TIME REPORT'!$A$6:$A$37,I$4)+SUMIFS('TIME REPORT'!$P$6:$P$37,'TIME REPORT'!$A$6:$A$37,I$4)/60-$AO$1))) | J32: =IF(COUNTIFS('TIME REPORT'!$A$6:$A$37,J$4,'TIME REPORT'!$Q$6:$Q$37,"Extra Hours")=0,"",IF(OR(WEEKDAY(DATE(HOLIDAYS!$E$3,HOLIDAYS!$E$2,J$4),2)>=6,COUNTIF(HOLIDAYS!$A$5:$A$199,DATE(HOLIDAYS!$E$3,HOLIDAYS!$E$2,J$4))>0),SUMIFS('TIME REPORT'!$N$6:$N$37,'TIME REPORT'!$A$6:$A$37,J$4)+SUMIFS('TIME REPORT'!$P$6:$P$37,'TIME REPORT'!$A$6:$A$37,J$4)/60,MAX(0,SUMIFS('TIME REPORT'!$N$6:$N$37,'TIME REPORT'!$A$6:$A$37,J$4)+SUMIFS('TIME REPORT'!$P$6:$P$37,'TIME REPORT'!$A$6:$A$37,J$4)/60-$AO$1))) | K32: =IF(COUNTIFS('TIME REPORT'!$A$6:$A$37,K$4,'TIME REPORT'!$Q$6:$Q$37,"Extra Hours")=0,"",IF(OR(WEEKDAY(DATE(HOLIDAYS!$E$3,HOLIDAYS!$E$2,K$4),2)>=6,COUNTIF(HOLIDAYS!$A$5:$A$199,DATE(HOLIDAYS!$E$3,HOLIDAYS!$E$2,K$4))>0),SUMIFS('TIME REPORT'!$N$6:$N$37,'TIME REPORT'!$A$6:$A$37,K$4)+SUMIFS('TIME REPORT'!$P$6:$P$37,'TIME REPORT'!$A$6:$A$37,K$4)/60,MAX(0,SUMIFS('TIME REPORT'!$N$6:$N$37,'TIME REPORT'!$A$6:$A$37,K$4)+SUMIFS('TIME REPORT'!$P$6:$P$37,'TIME REPORT'!$A$6:$A$37,K$4)/60-$AO$1))) | L32: =IF(COUNTIFS('TIME REPORT'!$A$6:$A$37,L$4,'TIME REPORT'!$Q$6:$Q$37,"Extra Hours")=0,"",IF(OR(WEEKDAY(DATE(HOLIDAYS!$E$3,HOLIDAYS!$E$2,L$4),2)>=6,COUNTIF(HOLIDAYS!$A$5:$A$199,DATE(HOLIDAYS!$E$3,HOLIDAYS!$E$2,L$4))>0),SUMIFS('TIME REPORT'!$N$6:$N$37,'TIME REPORT'!$A$6:$A$37,L$4)+SUMIFS('TIME REPORT'!$P$6:$P$37,'TIME REPORT'!$A$6:$A$37,L$4)/60,MAX(0,SUMIFS('TIME REPORT'!$N$6:$N$37,'TIME REPORT'!$A$6:$A$37,L$4)+SUMIFS('TIME REPORT'!$P$6:$P$37,'TIME REPORT'!$A$6:$A$37,L$4)/60-$AO$1))) | M32: =IF(COUNTIFS('TIME REPORT'!$A$6:$A$37,M$4,'TIME REPORT'!$Q$6:$Q$37,"Extra Hours")=0,"",IF(OR(WEEKDAY(DATE(HOLIDAYS!$E$3,HOLIDAYS!$E$2,M$4),2)>=6,COUNTIF(HOLIDAYS!$A$5:$A$199,DATE(HOLIDAYS!$E$3,HOLIDAYS!$E$2,M$4))>0),SUMIFS('TIME REPORT'!$N$6:$N$37,'TIME REPORT'!$A$6:$A$37,M$4)+SUMIFS('TIME REPORT'!$P$6:$P$37,'TIME REPORT'!$A$6:$A$37,M$4)/60,MAX(0,SUMIFS('TIME REPORT'!$N$6:$N$37,'TIME REPORT'!$A$6:$A$37,M$4)+SUMIFS('TIME REPORT'!$P$6:$P$37,'TIME REPORT'!$A$6:$A$37,M$4)/60-$AO$1))) | N32: =IF(COUNTIFS('TIME REPORT'!$A$6:$A$37,N$4,'TIME REPORT'!$Q$6:$Q$37,"Extra Hours")=0,"",IF(OR(WEEKDAY(DATE(HOLIDAYS!$E$3,HOLIDAYS!$E$2,N$4),2)>=6,COUNTIF(HOLIDAYS!$A$5:$A$199,DATE(HOLIDAYS!$E$3,HOLIDAYS!$E$2,N$4))>0),SUMIFS('TIME REPORT'!$N$6:$N$37,'TIME REPORT'!$A$6:$A$37,N$4)+SUMIFS('TIME REPORT'!$P$6:$P$37,'TIME REPORT'!$A$6:$A$37,N$4)/60,MAX(0,SUMIFS('TIME REPORT'!$N$6:$N$37,'TIME REPORT'!$A$6:$A$37,N$4)+SUMIFS('TIME REPORT'!$P$6:$P$37,'TIME REPORT'!$A$6:$A$37,N$4)/60-$AO$1))) | ... AK32: =IF(COUNTIFS('TIME REPORT'!$A$6:$A$37,AK$4,'TIME REPORT'!$Q$6:$Q$37,"Extra Hours")=0,"",IF(OR(WEEKDAY(DATE(HOLIDAYS!$E$3,HOLIDAYS!$E$2,AK$4),2)>=6,COUNTIF(HOLIDAYS!$A$5:$A$199,DATE(HOLIDAYS!$E$3,HOLIDAYS!$E$2,AK$4))>0),SUMIFS('TIME REPORT'!$N$6:$N$37,'TIME REPORT'!$A$6:$A$37,AK$4)+SUMIFS('TIME REPORT'!$P$6:$P$37,'TIME REPORT'!$A$6:$A$37,AK$4)/60,MAX(0,SUMIFS('TIME REPORT'!$N$6:$N$37,'TIME REPORT'!$A$6:$A$37,AK$4)+SUMIFS('TIME REPORT'!$P$6:$P$37,'TIME REPORT'!$A$6:$A$37,AK$4)/60-$AO$1))) | AL32: =SUM(G32:AK32) -> 0
A33: STANDARDS (A+B)-( C )-( D ) | G33: =IF(SUM(G22,G30)=0,"",SUM(G22,G30)-SUM(G31:G32)) | H33: =IF(SUM(H22,H30)=0,"",SUM(H22,H30)-SUM(H31:H32)) | I33: =IF(SUM(I22,I30)=0,"",SUM(I22,I30)-SUM(I31:I32)) | J33: =IF(SUM(J22,J30)=0,"",SUM(J22,J30)-SUM(J31:J32)) | K33: =IF(SUM(K22,K30)=0,"",SUM(K22,K30)-SUM(K31:K32)) | L33: =IF(SUM(L22,L30)=0,"",SUM(L22,L30)-SUM(L31:L32)) | M33: =IF(SUM(M22,M30)=0,"",SUM(M22,M30)-SUM(M31:M32)) | N33: =IF(SUM(N22,N30)=0,"",SUM(N22,N30)-SUM(N31:N32)) | ... AK33: =IF(SUM(AK22,AK30)=0,"",SUM(AK22,AK30)-SUM(AK31:AK32)) | AL33: =SUM(AL22,AL30)-SUM(AL31:AL32) -> 0 | AP33: =+AL22+AL30-AL33-AL32-AL31 -> 0 | AR33: =+AL22+AL30-AL31-AL32 -> 0
AL34: =+AL22+AL30-AL31-AL32-AL33 -> 0

Sheet TIME REPORT
A1: Dr. Virach & Associates | D1: TIME REPORT | M1: Division | O1: =+'TIME SHEET'!AH3
A2: Month | B2: ='TIME SHEET'!C3 -> ธันวาคม | D2: Year | E2: ='TIME SHEET'!F3 -> 2569 | G2: Prepared by | I2: ='TIME SHEET'!Z3 | M2: Approved by
A4: Date | B4: Hour | E4: Client's name | H4: Service Rendered | N4: Time
B5: In | C5: Out | N5: Hrs. | P5: Min | Q5: O.T./Extra
A6: =1 -> 1 | N6: =IF(IF(OR($B6="",$C6=""),"",(IF($C6="","",INT($C6)*60+ROUND(MOD($C6,1)*100,0))-IF($B6="","",IF($B6=0.01,0,INT($B6)*60+ROUND(MOD($B6,1)*100,0))))-MAX(0,MIN(IF($C6="","",INT($C6)*60+ROUND(MOD($C6,1)*100,0)),780)-MAX(IF($B6="","",IF($B6=0.01,0,INT($B6)*60+ROUND(MOD($B6,1)*100,0))),720))-MAX(0,MIN(IF($C6="","",INT($C6)*60+ROUND(MOD($C6,1)*100,0)),1260)-MAX(IF($B6="","",IF($B6=0.01,0,INT($B6)*60+ROUND(MOD($B6,1)*100,0))),1200)))="","",INT(IF(OR($B6="",$C6=""),"",(IF($C6="","",INT($C6)*60+ROUND(MOD($C6,1)*100,0))-IF($B6="","",IF($B6=0.01,0,INT($B6)*60+ROUND(MOD($B6,1)*100,0))))-MAX(0,MIN(IF($C6="","",INT($C6)*60+ROUND(MOD($C6,1)*100,0)),780)-MAX(IF($B6="","",IF($B6=0.01,0,INT($B6)*60+ROUND(MOD($B6,1)*100,0))),720))-MAX(0,MIN(IF($C6="","",INT($C6)*60+ROUND(MOD($C6,1)*100,0)),1260)-MAX(IF($B6="","",IF($B6=0.01,0,INT($B6)*60+ROUND(MOD($B6,1)*100,0))),1200)))/60)) | P6: =IF(IF(OR($B6="",$C6=""),"",(IF($C6="","",INT($C6)*60+ROUND(MOD($C6,1)*100,0))-IF($B6="","",IF($B6=0.01,0,INT($B6)*60+ROUND(MOD($B6,1)*100,0))))-MAX(0,MIN(IF($C6="","",INT($C6)*60+ROUND(MOD($C6,1)*100,0)),780)-MAX(IF($B6="","",IF($B6=0.01,0,INT($B6)*60+ROUND(MOD($B6,1)*100,0))),720))-MAX(0,MIN(IF($C6="","",INT($C6)*60+ROUND(MOD($C6,1)*100,0)),1260)-MAX(IF($B6="","",IF($B6=0.01,0,INT($B6)*60+ROUND(MOD($B6,1)*100,0))),1200)))="","",MOD(IF(OR($B6="",$C6=""),"",(IF($C6="","",INT($C6)*60+ROUND(MOD($C6,1)*100,0))-IF($B6="","",IF($B6=0.01,0,INT($B6)*60+ROUND(MOD($B6,1)*100,0))))-MAX(0,MIN(IF($C6="","",INT($C6)*60+ROUND(MOD($C6,1)*100,0)),780)-MAX(IF($B6="","",IF($B6=0.01,0,INT($B6)*60+ROUND(MOD($B6,1)*100,0))),720))-MAX(0,MIN(IF($C6="","",INT($C6)*60+ROUND(MOD($C6,1)*100,0)),1260)-MAX(IF($B6="","",IF($B6=0.01,0,INT($B6)*60+ROUND(MOD($B6,1)*100,0))),1200))),60))
A7: =IF($A6="","",IF($A6+1<=DAY(EOMONTH(DATE(HOLIDAYS!$E$3,HOLIDAYS!$E$2,1),0)),$A6+1,"")) -> 2 | N7: =IF(IF(OR($B7="",$C7=""),"",(IF($C7="","",INT($C7)*60+ROUND(MOD($C7,1)*100,0))-IF($B7="","",IF($B7=0.01,0,INT($B7)*60+ROUND(MOD($B7,1)*100,0))))-MAX(0,MIN(IF($C7="","",INT($C7)*60+ROUND(MOD($C7,1)*100,0)),780)-MAX(IF($B7="","",IF($B7=0.01,0,INT($B7)*60+ROUND(MOD($B7,1)*100,0))),720))-MAX(0,MIN(IF($C7="","",INT($C7)*60+ROUND(MOD($C7,1)*100,0)),1260)-MAX(IF($B7="","",IF($B7=0.01,0,INT($B7)*60+ROUND(MOD($B7,1)*100,0))),1200)))="","",INT(IF(OR($B7="",$C7=""),"",(IF($C7="","",INT($C7)*60+ROUND(MOD($C7,1)*100,0))-IF($B7="","",IF($B7=0.01,0,INT($B7)*60+ROUND(MOD($B7,1)*100,0))))-MAX(0,MIN(IF($C7="","",INT($C7)*60+ROUND(MOD($C7,1)*100,0)),780)-MAX(IF($B7="","",IF($B7=0.01,0,INT($B7)*60+ROUND(MOD($B7,1)*100,0))),720))-MAX(0,MIN(IF($C7="","",INT($C7)*60+ROUND(MOD($C7,1)*100,0)),1260)-MAX(IF($B7="","",IF($B7=0.01,0,INT($B7)*60+ROUND(MOD($B7,1)*100,0))),1200)))/60)) | P7: =IF(IF(OR($B7="",$C7=""),"",(IF($C7="","",INT($C7)*60+ROUND(MOD($C7,1)*100,0))-IF($B7="","",IF($B7=0.01,0,INT($B7)*60+ROUND(MOD($B7,1)*100,0))))-MAX(0,MIN(IF($C7="","",INT($C7)*60+ROUND(MOD($C7,1)*100,0)),780)-MAX(IF($B7="","",IF($B7=0.01,0,INT($B7)*60+ROUND(MOD($B7,1)*100,0))),720))-MAX(0,MIN(IF($C7="","",INT($C7)*60+ROUND(MOD($C7,1)*100,0)),1260)-MAX(IF($B7="","",IF($B7=0.01,0,INT($B7)*60+ROUND(MOD($B7,1)*100,0))),1200)))="","",MOD(IF(OR($B7="",$C7=""),"",(IF($C7="","",INT($C7)*60+ROUND(MOD($C7,1)*100,0))-IF($B7="","",IF($B7=0.01,0,INT($B7)*60+ROUND(MOD($B7,1)*100,0))))-MAX(0,MIN(IF($C7="","",INT($C7)*60+ROUND(MOD($C7,1)*100,0)),780)-MAX(IF($B7="","",IF($B7=0.01,0,INT($B7)*60+ROUND(MOD($B7,1)*100,0))),720))-MAX(0,MIN(IF($C7="","",INT($C7)*60+ROUND(MOD($C7,1)*100,0)),1260)-MAX(IF($B7="","",IF($B7=0.01,0,INT($B7)*60+ROUND(MOD($B7,1)*100,0))),1200))),60))
A8: =IF($A7="","",IF($A7+1<=DAY(EOMONTH(DATE(HOLIDAYS!$E$3,HOLIDAYS!$E$2,1),0)),$A7+1,"")) -> 3 | N8: =IF(IF(OR($B8="",$C8=""),"",(IF($C8="","",INT($C8)*60+ROUND(MOD($C8,1)*100,0))-IF($B8="","",IF($B8=0.01,0,INT($B8)*60+ROUND(MOD($B8,1)*100,0))))-MAX(0,MIN(IF($C8="","",INT($C8)*60+ROUND(MOD($C8,1)*100,0)),780)-MAX(IF($B8="","",IF($B8=0.01,0,INT($B8)*60+ROUND(MOD($B8,1)*100,0))),720))-MAX(0,MIN(IF($C8="","",INT($C8)*60+ROUND(MOD($C8,1)*100,0)),1260)-MAX(IF($B8="","",IF($B8=0.01,0,INT($B8)*60+ROUND(MOD($B8,1)*100,0))),1200)))="","",INT(IF(OR($B8="",$C8=""),"",(IF($C8="","",INT($C8)*60+ROUND(MOD($C8,1)*100,0))-IF($B8="","",IF($B8=0.01,0,INT($B8)*60+ROUND(MOD($B8,1)*100,0))))-MAX(0,MIN(IF($C8="","",INT($C8)*60+ROUND(MOD($C8,1)*100,0)),780)-MAX(IF($B8="","",IF($B8=0.01,0,INT($B8)*60+ROUND(MOD($B8,1)*100,0))),720))-MAX(0,MIN(IF($C8="","",INT($C8)*60+ROUND(MOD($C8,1)*100,0)),1260)-MAX(IF($B8="","",IF($B8=0.01,0,INT($B8)*60+ROUND(MOD($B8,1)*100,0))),1200)))/60)) | P8: =IF(IF(OR($B8="",$C8=""),"",(IF($C8="","",INT($C8)*60+ROUND(MOD($C8,1)*100,0))-IF($B8="","",IF($B8=0.01,0,INT($B8)*60+ROUND(MOD($B8,1)*100,0))))-MAX(0,MIN(IF($C8="","",INT($C8)*60+ROUND(MOD($C8,1)*100,0)),780)-MAX(IF($B8="","",IF($B8=0.01,0,INT($B8)*60+ROUND(MOD($B8,1)*100,0))),720))-MAX(0,MIN(IF($C8="","",INT($C8)*60+ROUND(MOD($C8,1)*100,0)),1260)-MAX(IF($B8="","",IF($B8=0.01,0,INT($B8)*60+ROUND(MOD($B8,1)*100,0))),1200)))="","",MOD(IF(OR($B8="",$C8=""),"",(IF($C8="","",INT($C8)*60+ROUND(MOD($C8,1)*100,0))-IF($B8="","",IF($B8=0.01,0,INT($B8)*60+ROUND(MOD($B8,1)*100,0))))-MAX(0,MIN(IF($C8="","",INT($C8)*60+ROUND(MOD($C8,1)*100,0)),780)-MAX(IF($B8="","",IF($B8=0.01,0,INT($B8)*60+ROUND(MOD($B8,1)*100,0))),720))-MAX(0,MIN(IF($C8="","",INT($C8)*60+ROUND(MOD($C8,1)*100,0)),1260)-MAX(IF($B8="","",IF($B8=0.01,0,INT($B8)*60+ROUND(MOD($B8,1)*100,0))),1200))),60))
